<sdf version='1.6'>
  <world name='default'>
    <light name='sun' type='directional'>
      <cast_shadows>1</cast_shadows>
      <pose frame=''>0 0 10 0 -0 0</pose>
      <diffuse>0.8 0.8 0.8 1</diffuse>
      <specular>0.1 0.1 0.1 1</specular>
      <attenuation>
        <range>1000</range>
        <constant>0.9</constant>
        <linear>0.01</linear>
        <quadratic>0.001</quadratic>
      </attenuation>
      <direction>-0.5 0.5 -1</direction>
    </light>
    <model name='ground_plane'>
      <static>1</static>
      <link name='link'>
        <collision name='collision'>
          <geometry>
            <plane>
              <normal>0 0 1</normal>
              <size>100 100</size>
            </plane>
          </geometry>
          <surface>
            <friction>
              <ode>
                <mu>100</mu>
                <mu2>50</mu2>
              </ode>
              <torsional>
                <ode/>
              </torsional>
            </friction>
            <contact>
              <ode/>
            </contact>
            <bounce/>
          </surface>
          <max_contacts>10</max_contacts>
        </collision>
        <visual name='visual'>
          <cast_shadows>0</cast_shadows>
          <geometry>
            <plane>
              <normal>0 0 1</normal>
              <size>100 100</size>
            </plane>
          </geometry>
          <material>
            <script>
              <uri>file://media/materials/scripts/gazebo.material</uri>
              <name>Gazebo/Grey</name>
            </script>
          </material>
        </visual>
        <self_collide>0</self_collide>
        <kinematic>0</kinematic>
        <gravity>1</gravity>
      </link>
    </model>
    <gravity>0 0 -9.8</gravity>
    <magnetic_field>6e-06 2.3e-05 -4.2e-05</magnetic_field>
    <atmosphere type='adiabatic'/>
    <physics name='default_physics' default='0' type='ode'>
      <max_step_size>0.001</max_step_size>
      <real_time_factor>1</real_time_factor>
      <real_time_update_rate>1000</real_time_update_rate>
    </physics>
    <scene>
      <ambient>0.4 0.4 0.4 1</ambient>
      <background>0.7 0.7 0.7 1</background>
      <shadows>1</shadows>
    </scene>
    <spherical_coordinates>
      <surface_model>EARTH_WGS84</surface_model>
      <latitude_deg>0</latitude_deg>
      <longitude_deg>0</longitude_deg>
      <elevation>0</elevation>
      <heading_deg>0</heading_deg>
    </spherical_coordinates>
    <model name='textured_shapes'>
      <pose frame=''>43.7623 37.8599 0.5 0 -0 0</pose>
      <link name='box'>
        <pose frame=''>0 -1.5 0 0 -0 0</pose>
        <collision name='collision'>
          <geometry>
            <box>
              <size>1 1 1</size>
            </box>
          </geometry>
          <max_contacts>10</max_contacts>
          <surface>
            <contact>
              <ode/>
            </contact>
            <bounce/>
            <friction>
              <torsional>
                <ode/>
              </torsional>
              <ode/>
            </friction>
          </surface>
        </collision>
        <visual name='visual'>
          <geometry>
            <box>
              <size>1 1 1</size>
            </box>
          </geometry>
          <material>
            <script>
              <uri>model://textured_shapes/materials/scripts</uri>
              <uri>model://textured_shapes/materials/textures</uri>
              <name>TexturedShape/Squares</name>
            </script>
          </material>
        </visual>
        <self_collide>0</self_collide>
        <inertial>
          <inertia>
            <ixx>1</ixx>
            <ixy>0</ixy>
            <ixz>0</ixz>
            <iyy>1</iyy>
            <iyz>0</iyz>
            <izz>1</izz>
          </inertia>
          <mass>1</mass>
        </inertial>
        <kinematic>0</kinematic>
        <gravity>1</gravity>
      </link>
      <link name='sphere'>
        <collision name='collision'>
          <geometry>
            <sphere>
              <radius>0.5</radius>
            </sphere>
          </geometry>
          <max_contacts>10</max_contacts>
          <surface>
            <contact>
              <ode/>
            </contact>
            <bounce/>
            <friction>
              <torsional>
                <ode/>
              </torsional>
              <ode/>
            </friction>
          </surface>
        </collision>
        <visual name='visual'>
          <geometry>
            <sphere>
              <radius>0.5</radius>
            </sphere>
          </geometry>
          <material>
            <script>
              <uri>model://textured_shapes/materials/scripts</uri>
              <uri>model://textured_shapes/materials/textures</uri>
              <name>TexturedShape/Squares</name>
            </script>
          </material>
        </visual>
        <self_collide>0</self_collide>
        <inertial>
          <inertia>
            <ixx>1</ixx>
            <ixy>0</ixy>
            <ixz>0</ixz>
            <iyy>1</iyy>
            <iyz>0</iyz>
            <izz>1</izz>
          </inertia>
          <mass>1</mass>
        </inertial>
        <kinematic>0</kinematic>
        <gravity>1</gravity>
      </link>
      <link name='cylinder'>
        <pose frame=''>0 1.5 0 0 -0 0</pose>
        <collision name='collision'>
          <geometry>
            <cylinder>
              <radius>0.5</radius>
              <length>1</length>
            </cylinder>
          </geometry>
          <max_contacts>10</max_contacts>
          <surface>
            <contact>
              <ode/>
            </contact>
            <bounce/>
            <friction>
              <torsional>
                <ode/>
              </torsional>
              <ode/>
            </friction>
          </surface>
        </collision>
        <visual name='visual'>
          <geometry>
            <cylinder>
              <radius>0.5</radius>
              <length>1</length>
            </cylinder>
          </geometry>
          <material>
            <script>
              <uri>model://textured_shapes/materials/scripts</uri>
              <uri>model://textured_shapes/materials/textures</uri>
              <name>TexturedShape/Squares</name>
            </script>
          </material>
        </visual>
        <self_collide>0</self_collide>
        <inertial>
          <inertia>
            <ixx>1</ixx>
            <ixy>0</ixy>
            <ixz>0</ixz>
            <iyy>1</iyy>
            <iyz>0</iyz>
            <izz>1</izz>
          </inertia>
          <mass>1</mass>
        </inertial>
        <kinematic>0</kinematic>
        <gravity>1</gravity>
      </link>
    </model>
    <state world_name='default'>
      <sim_time>1081 902000000</sim_time>
      <real_time>158 132326609</real_time>
      <wall_time>1559803166 495266647</wall_time>
      <iterations>154868</iterations>
      <model name='bottle1_1'>
        <pose frame=''>1.0254 -0.300059 0.899999 1.57079 -6e-06 1e-06</pose>
        <scale>1 1 1</scale>
        <link name='link_0'>
          <pose frame=''>1.0254 -0.300059 0.899999 1.57079 -6e-06 1e-06</pose>
          <velocity>0 0 0 0 -0 0</velocity>
          <acceleration>0 0 -2e-05 0.023417 -0.020899 0</acceleration>
          <wrench>0 0 -4e-06 0 -0 0</wrench>
        </link>
      </model>
      <model name='bottle2_0'>
        <pose frame=''>1.01106 0.3 0.9 1.57081 -1e-05 0</pose>
        <scale>1 1 1</scale>
        <link name='link_0'>
          <pose frame=''>1.01106 0.3 0.9 1.57081 -1e-05 0</pose>
          <velocity>0 0 0 0 -0 0</velocity>
          <acceleration>0 -1e-06 -0.021747 -1.16565 0.396101 1e-05</acceleration>
          <wrench>0 0 -0.002175 0 -0 0</wrench>
        </link>
      </model>
      <model name='ground_plane'>
        <pose frame=''>0 0 0 0 -0 0</pose>
        <scale>1 1 1</scale>
        <link name='link'>
          <pose frame=''>0 0 0 0 -0 0</pose>
          <velocity>0 0 0 0 -0 0</velocity>
          <acceleration>0 0 0 0 -0 0</acceleration>
          <wrench>0 0 0 0 -0 0</wrench>
        </link>
      </model>
      <model name='pallet_1'>
        <pose frame=''>0.449999 0 0.899995 1.57078 -8e-06 -1.57174</pose>
        <scale>1 1 1</scale>
        <link name='link_0'>
          <pose frame=''>0.449999 0 0.899995 1.57078 -8e-06 -1.57174</pose>
          <velocity>0 0 0 0 -0 0</velocity>
          <acceleration>-2.3e-05 0 -1.55922 1.79746 -1.21974 0.000131</acceleration>
          <wrench>-2.3e-05 0 -1.55922 0 -0 0</wrench>
        </link>
      </model>
      <model name='table_model'>
        <pose frame=''>-0.005743 0.813877 0 0 -0 0</pose>
        <scale>1 1 1</scale>
        <link name='table_top_link'>
          <pose frame=''>-0.005743 0.813877 0 0 -0 0</pose>
          <velocity>0 0 0 0 -0 0</velocity>
          <acceleration>0 0 0 0 -0 0</acceleration>
          <wrench>0 0 0 0 -0 0</wrench>
        </link>
      </model>
      <model name='textured_shapes'>
        <pose frame=''>43.7623 37.8599 0.5 0 -0 0</pose>
        <scale>1 1 1</scale>
        <link name='box'>
          <pose frame=''>43.7623 36.3599 0.5 0 -0 0</pose>
          <velocity>0 0 0 0 -0 0</velocity>
          <acceleration>0 0 0 0 -0 0</acceleration>
          <wrench>0 0 0 0 -0 0</wrench>
        </link>
        <link name='cylinder'>
          <pose frame=''>43.7623 39.3599 0.499996 0 -0 0</pose>
          <velocity>0 0 0 0 -0 0</velocity>
          <acceleration>0 0 -9.8 0 -0 0</acceleration>
          <wrench>0 0 -9.8 0 -0 0</wrench>
        </link>
        <link name='sphere'>
          <pose frame=''>43.7623 37.8599 0.5 0 -0 0</pose>
          <velocity>0 0 0 0 -0 0</velocity>
          <acceleration>0 0 0 0 -0 0</acceleration>
          <wrench>0 0 0 0 -0 0</wrench>
        </link>
      </model>
      <model name='wust_robot'>
        <pose frame=''>-0.005844 0.018979 0.022256 1e-06 1.5e-05 0.048677</pose>
        <scale>1 1 1</scale>
        <link name='L_Link1'>
          <pose frame=''>-0.260054 0.132934 1.17597 -3.09551 1.56044 -2.00136</pose>
          <velocity>2.2e-05 4e-06 -0.009358 0.009921 -0.007178 0.000279</velocity>
          <acceleration>0.013684 0.020893 -8.60171 2.78743 -1.23322 -0.409363</acceleration>
          <wrench>0.003093 0.004722 -1.94398 0 -0 0</wrench>
        </link>
        <link name='L_Link2'>
          <pose frame=''>-0.25717 0.251858 1.17464 1.60888 1.55917 -2.00937</pose>
          <velocity>1e-06 4e-06 -0.008505 0.00358 -0.010337 0.000392</velocity>
          <acceleration>-0.002146 0.02961 -7.79395 -0.138836 1.20074 -0.020846</acceleration>
          <wrench>-0.000453 0.006252 -1.64573 0 -0 0</wrench>
        </link>
        <link name='L_Link3'>
          <pose frame=''>-0.123502 0.397387 1.16963 -3.05268 1.55911 -1.95853</pose>
          <velocity>-3.8e-05 5e-05 -0.007084 0.003316 -0.012432 0.000401</velocity>
          <acceleration>-0.05369 0.066703 -6.42326 -0.464604 0.797012 2.67267</acceleration>
          <wrench>-0.00939 0.011666 -1.12343 0 -0 0</wrench>
        </link>
        <link name='L_Link4'>
          <pose frame=''>-0.121187 0.510194 1.16864 1.65128 1.55813 -1.96696</pose>
          <velocity>-8.3e-05 3.3e-05 -0.006649 -0.000168 -0.012542 0.000392</velocity>
          <acceleration>-0.082182 0.052687 -6.0161 2.33787 1.27344 0.779581</acceleration>
          <wrench>-0.011435 0.007331 -0.837087 0 -0 0</wrench>
        </link>
        <link name='L_Link5'>
          <pose frame=''>0.002876 0.642128 1.16431 -2.98567 1.558 -1.89152</pose>
          <velocity>-0.000103 8.4e-05 -0.005062 -0.003606 -0.014316 0.000365</velocity>
          <acceleration>-0.10589 0.091946 -4.78214 -1.36125 -0.8422 1.54469</acceleration>
          <wrench>-0.010316 0.008957 -0.46587 0 -0 0</wrench>
        </link>
        <link name='L_Link6'>
          <pose frame=''>0.002793 0.718467 1.16325 1.71642 1.55717 -1.90182</pose>
          <velocity>-0.000127 6.5e-05 -0.005292 -0.005288 -0.01186 0.000277</velocity>
          <acceleration>-0.121548 0.069838 -4.99058 0.402315 -1.44117 0.205583</acceleration>
          <wrench>-0.008629 0.004958 -0.354304 0 -0 0</wrench>
        </link>
        <link name='L_Link7'>
          <pose frame=''>0.093197 0.817034 1.15997 -2.99595 1.55717 -1.9018</pose>
          <velocity>-0.000129 8.5e-05 -0.004592 -0.005949 -0.011525 0.000254</velocity>
          <acceleration>-0.130034 0.085247 -4.59191 -0.450087 1.07336 0.25416</acceleration>
          <wrench>-0.009049 0.005932 -0.319558 0 -0 0</wrench>
        </link>
        <link name='L_left_finger'>
          <pose frame=''>0.09511 0.881763 1.15902 -0.009131 0.01152 0.834008</pose>
          <velocity>-0.000135 8.2e-05 -0.005037 -0.004388 -0.006187 0.000192</velocity>
          <acceleration>-0.138966 0.080656 -5.15193 2.46318 0.693854 0.488488</acceleration>
          <wrench>-0.003085 0.001791 -0.114389 0 -0 0</wrench>
        </link>
        <link name='L_right_finger'>
          <pose frame=''>0.144869 0.856074 1.15934 -0.009138 0.011512 0.83405</pose>
          <velocity>-0.000133 9.5e-05 -0.004286 -0.003671 -0.00888 0.000254</velocity>
          <acceleration>-0.136056 0.099732 -4.15854 -1.73801 0.670269 0.685931</acceleration>
          <wrench>-0.003021 0.002214 -0.092333 0 -0 0</wrench>
        </link>
        <link name='R_Link1'>
          <pose frame=''>-0.247838 -0.126931 1.17878 -0.055831 -1.56239 2.19722</pose>
          <velocity>1.4e-05 2e-06 -0.009358 -0.009216 -0.008089 -1.9e-05</velocity>
          <acceleration>0.009551 0.005152 -8.60051 1.0811 -0.981504 2.49859</acceleration>
          <wrench>0.002159 0.001164 -1.94362 0 -0 0</wrench>
        </link>
        <link name='R_Link2'>
          <pose frame=''>-0.233809 -0.24506 1.18002 -1.63178 -1.56367 2.20237</pose>
          <velocity>-1.2e-05 1.1e-05 -0.008504 -0.002601 -0.010629 0.000264</velocity>
          <acceleration>-0.013907 0.029277 -7.79264 -1.76251 1.5462 3.06525</acceleration>
          <wrench>-0.002937 0.006182 -1.64545 0 -0 0</wrench>
        </link>
        <link name='R_Link3'>
          <pose frame=''>-0.087062 -0.377437 1.18378 -0.144052 -1.56363 2.28544</pose>
          <velocity>-4e-05 2.1e-05 -0.007081 -0.002136 -0.012681 0.000469</velocity>
          <acceleration>-0.024657 0.043042 -6.42058 2.54105 0.335357 2.62575</acceleration>
          <wrench>-0.004313 0.007528 -1.12297 0 -0 0</wrench>
        </link>
        <link name='R_Link4'>
          <pose frame=''>-0.074175 -0.48953 1.18479 -1.73442 -1.5646 2.30501</pose>
          <velocity>-2.3e-05 4.6e-05 -0.006648 0.001317 -0.012429 0.000637</velocity>
          <acceleration>-0.010294 0.080049 -6.01629 -0.088213 1.20323 0.959833</acceleration>
          <wrench>-0.001432 0.011138 -0.837106 0 -0 0</wrench>
        </link>
        <link name='R_Link5'>
          <pose frame=''>0.061726 -0.609267 1.18809 -0.313282 -1.56439 2.45467</pose>
          <velocity>-7e-06 0.000116 -0.005062 0.004915 -0.013849 0.000872</velocity>
          <acceleration>0.007614 0.138427 -4.78379 0.112387 -1.031 -1.28427</acceleration>
          <wrench>0.000742 0.013485 -0.46603 0 -0 0</wrench>
        </link>
        <link name='R_Link6'>
          <pose frame=''>0.068807 -0.685283 1.18868 -1.92786 -1.56518 2.49845</pose>
          <velocity>3.5e-05 0.000132 -0.005293 0.006309 -0.011192 0.000949</velocity>
          <acceleration>0.052271 0.167075 -4.99505 -1.25988 -0.967785 -2.47538</acceleration>
          <wrench>0.003711 0.011861 -0.354621 0 -0 0</wrench>
        </link>
        <link name='R_Link7'>
          <pose frame=''>0.168063 -0.774957 1.19103 -0.356544 -1.56518 2.49794</pose>
          <velocity>8e-05 0.00021 -0.004598 0.006949 -0.010773 0.000973</velocity>
          <acceleration>0.095432 0.220065 -4.59847 -1.54242 1.32891 -2.27193</acceleration>
          <wrench>0.006641 0.015315 -0.320016 0 -0 0</wrench>
        </link>
        <link name='R_left_finger'>
          <pose frame=''>0.22317 -0.808982 1.1912 -0.001656 -0.007026 -1.52209</pose>
          <velocity>0.000111 0.000264 -0.004338 0.005413 -0.007837 0.000987</velocity>
          <acceleration>0.134555 0.291245 -4.25187 0.633993 0.206873 1.23344</acceleration>
          <wrench>0.002988 0.006467 -0.094405 0 -0 0</wrench>
        </link>
        <link name='R_right_finger'>
          <pose frame=''>0.176043 -0.839228 1.19148 -0.007037 0.001676 0.048721</pose>
          <velocity>0.000137 0.000216 -0.004995 0.00464 -0.006414 0.000997</velocity>
          <acceleration>0.170697 0.225433 -5.09216 -1.26226 -0.121485 1.03171</acceleration>
          <wrench>0.003772 0.004981 -0.112524 0 -0 0</wrench>
        </link>
        <link name='base_dummy'>
          <pose frame=''>-0.005844 0.018979 0.022256 1e-06 1.5e-05 0.048677</pose>
          <velocity>-2.6e-05 -1e-05 -0.009813 -2e-06 5.4e-05 -3.1e-05</velocity>
          <acceleration>-0.000566 -0.001118 -9.7991 -0.002577 0.054098 -0.030749</acceleration>
          <wrench>-0.058984 -0.11637 -1020.41 0 -0 0</wrench>
        </link>
        <link name='wheel_Link1'>
          <pose frame=''>-0.124765 0.330523 0.062471 1.57075 -0.057654 2.66667</pose>
          <velocity>0.000212 0.000922 -0.013146 -0.01287 0.006617 0.000971</velocity>
          <acceleration>0.214705 0.92071 -13.0997 -0.303502 0.334357 1.28975</acceleration>
          <wrench>0.168526 0.722682 -10.2822 0 -0 0</wrench>
        </link>
        <link name='wheel_Link2'>
          <pose frame=''>-0.657688 -0.012776 0.062472 1.57074 -0.058141 -1.52212</pose>
          <velocity>-0.000759 -0.000143 -0.011318 0.000553 -0.011343 0.000368</velocity>
          <acceleration>-0.758968 -0.141613 -11.2815 0.552571 1.22351 0.489316</acceleration>
          <wrench>-0.595728 -0.111155 -8.85505 0 -0 0</wrench>
        </link>
        <link name='wheel_Link3'>
          <pose frame=''>-0.093921 -0.302649 0.062471 1.57074 -0.057161 0.572278</pose>
          <velocity>0.000673 -0.000798 -0.013431 0.014893 0.009594 0.000411</velocity>
          <acceleration>0.671588 -0.798942 -13.3741 -0.814474 -0.169586 -2.59626</acceleration>
          <wrench>0.527141 -0.627104 -10.4976 0 -0 0</wrench>
        </link>
      </model>
      <light name='sun'>
        <pose frame=''>0 0 10 0 -0 0</pose>
      </light>
    </state>
    <gui fullscreen='0'>
      <camera name='user_camera'>
        <pose frame=''>2.63884 -0.728324 1.76093 0 0.355644 2.56819</pose>
        <view_controller>orbit</view_controller>
        <projection_type>perspective</projection_type>
      </camera>
    </gui>
    <model name='wust_robot'>
      <link name='base_dummy'>
        <pose frame=''>0 0 0 0 -0 0</pose>
        <inertial>
          <pose frame=''>-0.256089 -0.004553 0.473508 0 -0 0</pose>
          <mass>104.133</mass>
          <inertia>
            <ixx>26.5778</ixx>
            <ixy>-0.00723213</ixy>
            <ixz>-1.66262</ixz>
            <iyy>24.9707</iyy>
            <iyz>0.0320579</iyz>
            <izz>7.15858</izz>
          </inertia>
        </inertial>
        <collision name='base_dummy_fixed_joint_lump__base_link_collision'>
          <pose frame=''>0 0 0 0 -0 0</pose>
          <geometry>
            <mesh>
              <scale>1 1 1</scale>
              <uri>/home/zjy/catkin_ws/src/wust_robot/wust_robot_description/meshes/base_link.STL</uri>
            </mesh>
          </geometry>
          <surface>
            <contact>
              <ode/>
            </contact>
            <friction>
              <ode/>
              <torsional>
                <ode/>
              </torsional>
            </friction>
            <bounce/>
          </surface>
          <max_contacts>10</max_contacts>
        </collision>
        <collision name='base_dummy_fixed_joint_lump__L_Link0_collision_1'>
          <pose frame=''>-0.277217 0.076447 1.1543 3.14159 1.56054 -2.09613</pose>
          <geometry>
            <mesh>
              <scale>1 1 1</scale>
              <uri>/home/zjy/catkin_ws/src/wust_robot/wust_robot_description/meshes/L_Link0.STL</uri>
            </mesh>
          </geometry>
          <surface>
            <contact>
              <ode/>
            </contact>
            <friction>
              <ode/>
              <torsional>
                <ode/>
              </torsional>
            </friction>
            <bounce/>
          </surface>
          <max_contacts>10</max_contacts>
        </collision>
        <collision name='base_dummy_fixed_joint_lump__R_Link0_collision_2'>
          <pose frame=''>-0.282475 -0.075449 1.15595 -0 -1.56231 2.09271</pose>
          <geometry>
            <mesh>
              <scale>1 1 1</scale>
              <uri>/home/zjy/catkin_ws/src/wust_robot/wust_robot_description/meshes/R_Link0.STL</uri>
            </mesh>
          </geometry>
          <surface>
            <contact>
              <ode/>
            </contact>
            <friction>
              <ode/>
              <torsional>
                <ode/>
              </torsional>
            </friction>
            <bounce/>
          </surface>
          <max_contacts>10</max_contacts>
        </collision>
        <visual name='base_dummy_fixed_joint_lump__base_link_visual'>
          <pose frame=''>0 0 0 0 -0 0</pose>
          <geometry>
            <mesh>
              <scale>1 1 1</scale>
              <uri>/home/zjy/catkin_ws/src/wust_robot/wust_robot_description/meshes/base_link.STL</uri>
            </mesh>
          </geometry>
          <material>
            <script>
              <uri>file://media/materials/scripts/gazebo.material</uri>
              <name>Gazebo/Grey</name>
            </script>
          </material>
        </visual>
        <visual name='base_dummy_fixed_joint_lump__L_Link0_visual_1'>
          <pose frame=''>-0.277217 0.076447 1.1543 3.14159 1.56054 -2.09613</pose>
          <geometry>
            <mesh>
              <scale>1 1 1</scale>
              <uri>/home/zjy/catkin_ws/src/wust_robot/wust_robot_description/meshes/L_Link0.STL</uri>
            </mesh>
          </geometry>
          <material>
            <ambient>0.792157 0.819608 0.933333 1</ambient>
            <diffuse>0.792157 0.819608 0.933333 1</diffuse>
            <specular>0.1 0.1 0.1 1</specular>
            <emissive>0 0 0 0</emissive>
            <script>
              <uri>__default__</uri>
              <name>__default__</name>
            </script>
          </material>
        </visual>
        <visual name='base_dummy_fixed_joint_lump__R_Link0_visual_2'>
          <pose frame=''>-0.282475 -0.075449 1.15595 -0 -1.56231 2.09271</pose>
          <geometry>
            <mesh>
              <scale>1 1 1</scale>
              <uri>/home/zjy/catkin_ws/src/wust_robot/wust_robot_description/meshes/R_Link0.STL</uri>
            </mesh>
          </geometry>
          <material>
            <ambient>0.792157 0.819608 0.933333 1</ambient>
            <diffuse>0.792157 0.819608 0.933333 1</diffuse>
            <specular>0.1 0.1 0.1 1</specular>
            <emissive>0 0 0 0</emissive>
            <script>
              <uri>__default__</uri>
              <name>__default__</name>
            </script>
          </material>
        </visual>
        <velocity_decay/>
        <velocity_decay/>
        <gravity>1</gravity>
        <velocity_decay/>
        <self_collide>0</self_collide>
        <kinematic>0</kinematic>
      </link>
      <link name='L_Link1'>
        <pose frame=''>-0.248382 0.126191 1.15371 -3.14073 1.56054 -2.09526</pose>
        <inertial>
          <pose frame=''>-4e-05 -0.015653 0.060113 0 -0 0</pose>
          <mass>0.225999</mass>
          <inertia>
            <ixx>0.000855101</ixx>
            <ixy>1.28543e-07</ixy>
            <ixz>6.24869e-07</ixz>
            <iyy>0.000896246</iyy>
            <iyz>6.58583e-05</iyz>
            <izz>0.000416139</izz>
          </inertia>
        </inertial>
        <collision name='L_Link1_collision'>
          <pose frame=''>0 0 0 0 -0 0</pose>
          <geometry>
            <mesh>
              <scale>1 1 1</scale>
              <uri>/home/zjy/catkin_ws/src/wust_robot/wust_robot_description/meshes/L_Link1.STL</uri>
            </mesh>
          </geometry>
          <surface>
            <contact>
              <ode/>
            </contact>
            <friction>
              <ode/>
              <torsional>
                <ode/>
              </torsional>
            </friction>
            <bounce/>
          </surface>
          <max_contacts>10</max_contacts>
        </collision>
        <visual name='L_Link1_visual'>
          <pose frame=''>0 0 0 0 -0 0</pose>
          <geometry>
            <mesh>
              <scale>1 1 1</scale>
              <uri>/home/zjy/catkin_ws/src/wust_robot/wust_robot_description/meshes/L_Link1.STL</uri>
            </mesh>
          </geometry>
          <material>
            <script>
              <uri>file://media/materials/scripts/gazebo.material</uri>
              <name>Gazebo/FlatBlack</name>
            </script>
          </material>
        </visual>
        <gravity>1</gravity>
        <velocity_decay/>
        <self_collide>0</self_collide>
        <kinematic>0</kinematic>
      </link>
      <joint name='L_joint1' type='revolute'>
        <child>L_Link1</child>
        <parent>base_dummy</parent>
        <axis>
          <xyz>0.501472 0.865113 -0.010255</xyz>
          <limit>
            <lower>-3.05</lower>
            <upper>3.05</upper>
            <effort>90</effort>
            <velocity>1.31</velocity>
          </limit>
          <dynamics>
            <spring_reference>0</spring_reference>
            <spring_stiffness>0</spring_stiffness>
          </dynamics>
          <use_parent_model_frame>1</use_parent_model_frame>
        </axis>
      </joint>
      <link name='L_Link2'>
        <pose frame=''>-0.239714 0.244834 1.15241 1.57166 1.56054 -2.09526</pose>
        <inertial>
          <pose frame=''>0.000857 -0.068856 -0.021948 0 -0 0</pose>
          <mass>0.211155</mass>
          <inertia>
            <ixx>0.000996806</ixx>
            <ixy>7.35505e-06</ixy>
            <ixz>3.3042e-06</ixz>
            <iyy>0.000405577</iyy>
            <iyz>-0.000263492</iyz>
            <izz>0.000942075</izz>
          </inertia>
        </inertial>
        <collision name='L_Link2_collision'>
          <pose frame=''>0 0 0 0 -0 0</pose>
          <geometry>
            <mesh>
              <scale>1 1 1</scale>
              <uri>/home/zjy/catkin_ws/src/wust_robot/wust_robot_description/meshes/L_Link2.STL</uri>
            </mesh>
          </geometry>
          <surface>
            <contact>
              <ode/>
            </contact>
            <friction>
              <ode/>
              <torsional>
                <ode/>
              </torsional>
            </friction>
            <bounce/>
          </surface>
          <max_contacts>10</max_contacts>
        </collision>
        <visual name='L_Link2_visual'>
          <pose frame=''>0 0 0 0 -0 0</pose>
          <geometry>
            <mesh>
              <scale>1 1 1</scale>
              <uri>/home/zjy/catkin_ws/src/wust_robot/wust_robot_description/meshes/L_Link2.STL</uri>
            </mesh>
          </geometry>
          <material>
            <script>
              <uri>file://media/materials/scripts/gazebo.material</uri>
              <name>Gazebo/FlatBlack</name>
            </script>
          </material>
        </visual>
        <gravity>1</gravity>
        <velocity_decay/>
        <self_collide>0</self_collide>
        <kinematic>0</kinematic>
      </link>
      <joint name='L_joint2' type='revolute'>
        <child>L_Link2</child>
        <parent>L_Link1</parent>
        <axis>
          <xyz>-0.865161 0.501495 -9e-06</xyz>
          <limit>
            <lower>-2.09</lower>
            <upper>2.09</upper>
            <effort>90</effort>
            <velocity>1.31</velocity>
          </limit>
          <dynamics>
            <spring_reference>0</spring_reference>
            <spring_stiffness>0</spring_stiffness>
          </dynamics>
          <use_parent_model_frame>1</use_parent_model_frame>
        </axis>
      </joint>
      <link name='L_Link3'>
        <pose frame=''>-0.099122 0.383693 1.14764 -3.14073 1.56054 -2.09526</pose>
        <inertial>
          <pose frame=''>-0.000502 -0.016173 0.058519 0 -0 0</pose>
          <mass>0.174901</mass>
          <inertia>
            <ixx>0.000566836</ixx>
            <ixy>1.50177e-07</ixy>
            <ixz>3.02203e-07</ixz>
            <iyy>0.000579069</iyy>
            <iyz>3.49865e-05</iyz>
            <izz>0.00024042</izz>
          </inertia>
        </inertial>
        <collision name='L_Link3_collision'>
          <pose frame=''>0 0 0 0 -0 0</pose>
          <geometry>
            <mesh>
              <scale>1 1 1</scale>
              <uri>/home/zjy/catkin_ws/src/wust_robot/wust_robot_description/meshes/L_Link3.STL</uri>
            </mesh>
          </geometry>
          <surface>
            <contact>
              <ode/>
            </contact>
            <friction>
              <ode/>
              <torsional>
                <ode/>
              </torsional>
            </friction>
            <bounce/>
          </surface>
          <max_contacts>10</max_contacts>
        </collision>
        <visual name='L_Link3_visual'>
          <pose frame=''>0 0 0 0 -0 0</pose>
          <geometry>
            <mesh>
              <scale>1 1 1</scale>
              <uri>/home/zjy/catkin_ws/src/wust_robot/wust_robot_description/meshes/L_Link3.STL</uri>
            </mesh>
          </geometry>
          <material>
            <script>
              <uri>file://media/materials/scripts/gazebo.material</uri>
              <name>Gazebo/FlatBlack</name>
            </script>
          </material>
        </visual>
        <gravity>1</gravity>
        <velocity_decay/>
        <self_collide>0</self_collide>
        <kinematic>0</kinematic>
      </link>
      <joint name='L_joint3' type='revolute'>
        <child>L_Link3</child>
        <parent>L_Link2</parent>
        <axis>
          <xyz>0.501472 0.865113 -0.010255</xyz>
          <limit>
            <lower>-3.05</lower>
            <upper>3.05</upper>
            <effort>67</effort>
            <velocity>1.31</velocity>
          </limit>
          <dynamics>
            <spring_reference>0</spring_reference>
            <spring_stiffness>0</spring_stiffness>
          </dynamics>
          <use_parent_model_frame>1</use_parent_model_frame>
        </axis>
      </joint>
      <link name='L_Link4'>
        <pose frame=''>-0.09132 0.496255 1.14684 1.57166 1.56054 -2.09526</pose>
        <inertial>
          <pose frame=''>0.000816 -0.067379 -0.022767 0 -0 0</pose>
          <mass>0.139141</mass>
          <inertia>
            <ixx>0.000567296</ixx>
            <ixy>4.51474e-06</ixy>
            <ixz>1.91083e-06</ixz>
            <iyy>0.000225919</iyy>
            <iyz>-0.000151217</iyz>
            <izz>0.000540296</izz>
          </inertia>
        </inertial>
        <collision name='L_Link4_collision'>
          <pose frame=''>0 0 0 0 -0 0</pose>
          <geometry>
            <mesh>
              <scale>1 1 1</scale>
              <uri>/home/zjy/catkin_ws/src/wust_robot/wust_robot_description/meshes/L_Link4.STL</uri>
            </mesh>
          </geometry>
          <surface>
            <contact>
              <ode/>
            </contact>
            <friction>
              <ode/>
              <torsional>
                <ode/>
              </torsional>
            </friction>
            <bounce/>
          </surface>
          <max_contacts>10</max_contacts>
        </collision>
        <visual name='L_Link4_visual'>
          <pose frame=''>0 0 0 0 -0 0</pose>
          <geometry>
            <mesh>
              <scale>1 1 1</scale>
              <uri>/home/zjy/catkin_ws/src/wust_robot/wust_robot_description/meshes/L_Link4.STL</uri>
            </mesh>
          </geometry>
          <material>
            <script>
              <uri>file://media/materials/scripts/gazebo.material</uri>
              <name>Gazebo/FlatBlack</name>
            </script>
          </material>
        </visual>
        <gravity>1</gravity>
        <velocity_decay/>
        <self_collide>0</self_collide>
        <kinematic>0</kinematic>
      </link>
      <joint name='L_joint4' type='revolute'>
        <child>L_Link4</child>
        <parent>L_Link3</parent>
        <axis>
          <xyz>-0.865161 0.501495 -9e-06</xyz>
          <limit>
            <lower>-2.09</lower>
            <upper>2.09</upper>
            <effort>67</effort>
            <velocity>1.31</velocity>
          </limit>
          <dynamics>
            <spring_reference>0</spring_reference>
            <spring_stiffness>0</spring_stiffness>
          </dynamics>
          <use_parent_model_frame>1</use_parent_model_frame>
        </axis>
      </joint>
      <link name='L_Link5'>
        <pose frame=''>0.039018 0.622006 1.14287 -3.14073 1.56054 -2.09526</pose>
        <inertial>
          <pose frame=''>-4.3e-05 -0.012206 0.030908 0 -0 0</pose>
          <mass>0.0974186</mass>
          <inertia>
            <ixx>0.000193994</ixx>
            <ixy>-1.08151e-08</ixy>
            <ixz>1.12866e-07</ixz>
            <iyy>0.000192392</iyy>
            <iyz>2.593e-05</iyz>
            <izz>0.000116052</izz>
          </inertia>
        </inertial>
        <collision name='L_Link5_collision'>
          <pose frame=''>0 0 0 0 -0 0</pose>
          <geometry>
            <mesh>
              <scale>1 1 1</scale>
              <uri>/home/zjy/catkin_ws/src/wust_robot/wust_robot_description/meshes/L_Link5.STL</uri>
            </mesh>
          </geometry>
          <surface>
            <contact>
              <ode/>
            </contact>
            <friction>
              <ode/>
              <torsional>
                <ode/>
              </torsional>
            </friction>
            <bounce/>
          </surface>
          <max_contacts>10</max_contacts>
        </collision>
        <visual name='L_Link5_visual'>
          <pose frame=''>0 0 0 0 -0 0</pose>
          <geometry>
            <mesh>
              <scale>1 1 1</scale>
              <uri>/home/zjy/catkin_ws/src/wust_robot/wust_robot_description/meshes/L_Link5.STL</uri>
            </mesh>
          </geometry>
          <material>
            <script>
              <uri>file://media/materials/scripts/gazebo.material</uri>
              <name>Gazebo/FlatBlack</name>
            </script>
          </material>
        </visual>
        <gravity>1</gravity>
        <velocity_decay/>
        <self_collide>0</self_collide>
        <kinematic>0</kinematic>
      </link>
      <joint name='L_joint5' type='revolute'>
        <child>L_Link5</child>
        <parent>L_Link4</parent>
        <axis>
          <xyz>0.501472 0.865113 -0.010255</xyz>
          <limit>
            <lower>-3.05</lower>
            <upper>3.05</upper>
            <effort>67</effort>
            <velocity>1.57</velocity>
          </limit>
          <dynamics>
            <spring_reference>0</spring_reference>
            <spring_stiffness>0</spring_stiffness>
          </dynamics>
          <use_parent_model_frame>1</use_parent_model_frame>
        </axis>
      </joint>
      <link name='L_Link6'>
        <pose frame=''>0.04265 0.698262 1.14204 1.57166 1.56054 -2.09526</pose>
        <inertial>
          <pose frame=''>0.000578 -0.046301 -0.020592 0 -0 0</pose>
          <mass>0.0709946</mass>
          <inertia>
            <ixx>0.00015034</ixx>
            <ixy>9.87376e-07</ixy>
            <ixz>4.30166e-07</ixz>
            <iyy>6.97108e-05</iyy>
            <iyz>-3.5344e-05</iyz>
            <izz>0.000145966</izz>
          </inertia>
        </inertial>
        <collision name='L_Link6_collision'>
          <pose frame=''>0 0 0 0 -0 0</pose>
          <geometry>
            <mesh>
              <scale>1 1 1</scale>
              <uri>/home/zjy/catkin_ws/src/wust_robot/wust_robot_description/meshes/L_Link6.STL</uri>
            </mesh>
          </geometry>
          <surface>
            <contact>
              <ode/>
            </contact>
            <friction>
              <ode/>
              <torsional>
                <ode/>
              </torsional>
            </friction>
            <bounce/>
          </surface>
          <max_contacts>10</max_contacts>
        </collision>
        <visual name='L_Link6_visual'>
          <pose frame=''>0 0 0 0 -0 0</pose>
          <geometry>
            <mesh>
              <scale>1 1 1</scale>
              <uri>/home/zjy/catkin_ws/src/wust_robot/wust_robot_description/meshes/L_Link6.STL</uri>
            </mesh>
          </geometry>
          <material>
            <script>
              <uri>file://media/materials/scripts/gazebo.material</uri>
              <name>Gazebo/FlatBlack</name>
            </script>
          </material>
        </visual>
        <gravity>1</gravity>
        <velocity_decay/>
        <self_collide>0</self_collide>
        <kinematic>0</kinematic>
      </link>
      <joint name='L_joint6' type='revolute'>
        <child>L_Link6</child>
        <parent>L_Link5</parent>
        <axis>
          <xyz>-0.865161 0.501495 -9e-06</xyz>
          <limit>
            <lower>-2.09</lower>
            <upper>2.09</upper>
            <effort>67</effort>
            <velocity>1.57</velocity>
          </limit>
          <dynamics>
            <spring_reference>0</spring_reference>
            <spring_stiffness>0</spring_stiffness>
          </dynamics>
          <use_parent_model_frame>1</use_parent_model_frame>
        </axis>
      </joint>
      <link name='L_Link7'>
        <pose frame=''>0.137744 0.792323 1.1391 -3.14073 1.56054 -2.09526</pose>
        <inertial>
          <pose frame=''>4.6e-05 1e-06 0.021461 0 -0 0</pose>
          <mass>0.0695915</mass>
          <inertia>
            <ixx>0.000100578</ixx>
            <ixy>-5.19959e-08</ixy>
            <ixz>-5.45712e-08</ixz>
            <iyy>8.8599e-05</iyy>
            <iyz>6.1563e-09</iyz>
            <izz>8.88087e-05</izz>
          </inertia>
        </inertial>
        <collision name='L_Link7_collision'>
          <pose frame=''>0 0 0 0 -0 0</pose>
          <geometry>
            <mesh>
              <scale>1 1 1</scale>
              <uri>/home/zjy/catkin_ws/src/wust_robot/wust_robot_description/meshes/L_Link7.STL</uri>
            </mesh>
          </geometry>
          <surface>
            <contact>
              <ode>
                <kp>1e+08</kp>
                <kd>1</kd>
                <max_vel>0.1</max_vel>
                <min_depth>0.01</min_depth>
              </ode>
            </contact>
            <friction>
              <ode>
                <mu>200</mu>
                <mu2>200</mu2>
              </ode>
              <torsional>
                <ode/>
              </torsional>
            </friction>
            <bounce/>
          </surface>
          <max_contacts>10</max_contacts>
        </collision>
        <visual name='L_Link7_visual'>
          <pose frame=''>0 0 0 0 -0 0</pose>
          <geometry>
            <mesh>
              <scale>1 1 1</scale>
              <uri>/home/zjy/catkin_ws/src/wust_robot/wust_robot_description/meshes/L_Link7.STL</uri>
            </mesh>
          </geometry>
          <material>
            <ambient>0.792157 0.819608 0.933333 1</ambient>
            <diffuse>0.792157 0.819608 0.933333 1</diffuse>
            <specular>0.1 0.1 0.1 1</specular>
            <emissive>0 0 0 0</emissive>
            <script>
              <uri>__default__</uri>
              <name>__default__</name>
            </script>
          </material>
        </visual>
        <gravity>1</gravity>
        <velocity_decay/>
        <self_collide>0</self_collide>
        <kinematic>0</kinematic>
      </link>
      <joint name='L_joint7' type='revolute'>
        <child>L_Link7</child>
        <parent>L_Link6</parent>
        <axis>
          <xyz>0.501472 0.865113 -0.010255</xyz>
          <limit>
            <lower>-3.05</lower>
            <upper>3.05</upper>
            <effort>33</effort>
            <velocity>1.57</velocity>
          </limit>
          <dynamics>
            <spring_reference>0</spring_reference>
            <spring_stiffness>0</spring_stiffness>
          </dynamics>
          <use_parent_model_frame>1</use_parent_model_frame>
        </axis>
      </joint>
      <link name='L_left_finger'>
        <pose frame=''>0.142805 0.856886 1.1384 -0.006415 0.008904 0.785362</pose>
        <inertial>
          <pose frame=''>0.03203 0.019158 1.7e-05 0 -0 0</pose>
          <mass>0.0222031</mass>
          <inertia>
            <ixx>2.94895e-06</ixx>
            <ixy>-2.74026e-06</ixy>
            <ixz>3.48999e-09</ixz>
            <iyy>1.31997e-05</iyy>
            <iyz>-1.52394e-09</iyz>
            <izz>1.31922e-05</izz>
          </inertia>
        </inertial>
        <collision name='L_left_finger_collision'>
          <pose frame=''>0 0 0 0 -0 0</pose>
          <geometry>
            <mesh>
              <scale>1 1 1</scale>
              <uri>/home/zjy/catkin_ws/src/wust_robot/wust_robot_description/meshes/L_left_finger.STL</uri>
            </mesh>
          </geometry>
          <surface>
            <contact>
              <ode>
                <kp>1e+08</kp>
                <kd>1</kd>
                <max_vel>0.1</max_vel>
                <min_depth>0.01</min_depth>
              </ode>
            </contact>
            <friction>
              <ode>
                <mu>200</mu>
                <mu2>200</mu2>
              </ode>
              <torsional>
                <ode/>
              </torsional>
            </friction>
            <bounce/>
          </surface>
          <max_contacts>10</max_contacts>
        </collision>
        <visual name='L_left_finger_visual'>
          <pose frame=''>0 0 0 0 -0 0</pose>
          <geometry>
            <mesh>
              <scale>1 1 1</scale>
              <uri>/home/zjy/catkin_ws/src/wust_robot/wust_robot_description/meshes/L_left_finger.STL</uri>
            </mesh>
          </geometry>
          <material>
            <ambient>0.792157 0.819608 0.933333 1</ambient>
            <diffuse>0.792157 0.819608 0.933333 1</diffuse>
            <specular>0.1 0.1 0.1 1</specular>
            <emissive>0 0 0 0</emissive>
            <script>
              <uri>__default__</uri>
              <name>__default__</name>
            </script>
          </material>
        </visual>
        <gravity>1</gravity>
        <velocity_decay/>
        <self_collide>0</self_collide>
        <kinematic>0</kinematic>
      </link>
      <joint name='L_left_joint' type='revolute'>
        <child>L_left_finger</child>
        <parent>L_Link7</parent>
        <axis>
          <xyz>0.001761 0.010832 0.99994</xyz>
          <limit>
            <lower>-0.35</lower>
            <upper>0.35</upper>
            <effort>33</effort>
            <velocity>1.57</velocity>
          </limit>
          <dynamics>
            <spring_reference>0</spring_reference>
            <spring_stiffness>0</spring_stiffness>
          </dynamics>
          <use_parent_model_frame>1</use_parent_model_frame>
        </axis>
      </joint>
      <link name='L_right_finger'>
        <pose frame=''>0.191255 0.828804 1.13861 -0.006415 0.008904 0.785362</pose>
        <inertial>
          <pose frame=''>0.037435 -0.000661 -1.7e-05 0 -0 0</pose>
          <mass>0.0222032</mass>
          <inertia>
            <ixx>2.96928e-06</ixx>
            <ixy>-2.85847e-06</ixy>
            <ixz>-2.56669e-09</ixz>
            <iyy>1.31704e-05</iyy>
            <iyz>-2.89707e-09</iyz>
            <izz>1.31832e-05</izz>
          </inertia>
        </inertial>
        <collision name='L_right_finger_collision'>
          <pose frame=''>0 0 0 0 -0 0</pose>
          <geometry>
            <mesh>
              <scale>1 1 1</scale>
              <uri>/home/zjy/catkin_ws/src/wust_robot/wust_robot_description/meshes/L_right_finger.STL</uri>
            </mesh>
          </geometry>
          <surface>
            <contact>
              <ode>
                <kp>1e+08</kp>
                <kd>1</kd>
                <max_vel>0.1</max_vel>
                <min_depth>0.01</min_depth>
              </ode>
            </contact>
            <friction>
              <ode>
                <mu>200</mu>
                <mu2>200</mu2>
              </ode>
              <torsional>
                <ode/>
              </torsional>
            </friction>
            <bounce/>
          </surface>
          <max_contacts>10</max_contacts>
        </collision>
        <visual name='L_right_finger_visual'>
          <pose frame=''>0 0 0 0 -0 0</pose>
          <geometry>
            <mesh>
              <scale>1 1 1</scale>
              <uri>/home/zjy/catkin_ws/src/wust_robot/wust_robot_description/meshes/L_right_finger.STL</uri>
            </mesh>
          </geometry>
          <material>
            <ambient>0.792157 0.819608 0.933333 1</ambient>
            <diffuse>0.792157 0.819608 0.933333 1</diffuse>
            <specular>0.1 0.1 0.1 1</specular>
            <emissive>0 0 0 0</emissive>
            <script>
              <uri>__default__</uri>
              <name>__default__</name>
            </script>
          </material>
        </visual>
        <gravity>1</gravity>
        <velocity_decay/>
        <self_collide>0</self_collide>
        <kinematic>0</kinematic>
      </link>
      <joint name='L_right_joint' type='revolute'>
        <child>L_right_finger</child>
        <parent>L_Link7</parent>
        <axis>
          <xyz>0.001761 0.010832 0.99994</xyz>
          <limit>
            <lower>-0.35</lower>
            <upper>0.35</upper>
            <effort>33</effort>
            <velocity>1.57</velocity>
          </limit>
          <dynamics>
            <spring_reference>0</spring_reference>
            <spring_stiffness>0</spring_stiffness>
          </dynamics>
          <use_parent_model_frame>1</use_parent_model_frame>
        </axis>
      </joint>
      <link name='R_Link1'>
        <pose frame=''>-0.248825 -0.13396 1.15652 -0 -1.56231 2.09271</pose>
        <inertial>
          <pose frame=''>-8.8e-05 -0.015652 0.060116 0 -0 0</pose>
          <mass>0.225989</mass>
          <inertia>
            <ixx>0.000855056</ixx>
            <ixy>2.56077e-07</ixy>
            <ixz>8.2956e-07</ixz>
            <iyy>0.000896207</iyy>
            <iyz>6.58679e-05</iyz>
            <izz>0.000416131</izz>
          </inertia>
        </inertial>
        <collision name='R_Link1_collision'>
          <pose frame=''>0 0 0 0 -0 0</pose>
          <geometry>
            <mesh>
              <scale>1 1 1</scale>
              <uri>/home/zjy/catkin_ws/src/wust_robot/wust_robot_description/meshes/R_Link1.STL</uri>
            </mesh>
          </geometry>
          <surface>
            <contact>
              <ode/>
            </contact>
            <friction>
              <ode/>
              <torsional>
                <ode/>
              </torsional>
            </friction>
            <bounce/>
          </surface>
          <max_contacts>10</max_contacts>
        </collision>
        <visual name='R_Link1_visual'>
          <pose frame=''>0 0 0 0 -0 0</pose>
          <geometry>
            <mesh>
              <scale>1 1 1</scale>
              <uri>/home/zjy/catkin_ws/src/wust_robot/wust_robot_description/meshes/R_Link1.STL</uri>
            </mesh>
          </geometry>
          <material>
            <script>
              <uri>file://media/materials/scripts/gazebo.material</uri>
              <name>Gazebo/FlatBlack</name>
            </script>
          </material>
        </visual>
        <gravity>1</gravity>
        <velocity_decay/>
        <self_collide>0</self_collide>
        <kinematic>0</kinematic>
      </link>
      <joint name='R_joint1' type='revolute'>
        <child>R_Link1</child>
        <parent>base_dummy</parent>
        <axis>
          <xyz>-0.498525 0.866834 -0.008487</xyz>
          <limit>
            <lower>-3.05</lower>
            <upper>3.05</upper>
            <effort>90</effort>
            <velocity>1.31</velocity>
          </limit>
          <dynamics>
            <spring_reference>0</spring_reference>
            <spring_stiffness>0</spring_stiffness>
          </dynamics>
          <use_parent_model_frame>1</use_parent_model_frame>
        </axis>
      </joint>
      <link name='R_Link2'>
        <pose frame=''>-0.24056 -0.252632 1.15779 -1.5708 -1.56231 2.09271</pose>
        <inertial>
          <pose frame=''>0.000855 -0.068856 -0.021948 0 -0 0</pose>
          <mass>0.211155</mass>
          <inertia>
            <ixx>0.000996807</ixx>
            <ixy>7.34047e-06</ixy>
            <ixz>3.29819e-06</ixz>
            <iyy>0.000405577</iyy>
            <iyz>-0.000263492</iyz>
            <izz>0.000942076</izz>
          </inertia>
        </inertial>
        <collision name='R_Link2_collision'>
          <pose frame=''>0 0 0 0 -0 0</pose>
          <geometry>
            <mesh>
              <scale>1 1 1</scale>
              <uri>/home/zjy/catkin_ws/src/wust_robot/wust_robot_description/meshes/R_Link2.STL</uri>
            </mesh>
          </geometry>
          <surface>
            <contact>
              <ode/>
            </contact>
            <friction>
              <ode/>
              <torsional>
                <ode/>
              </torsional>
            </friction>
            <bounce/>
          </surface>
          <max_contacts>10</max_contacts>
        </collision>
        <visual name='R_Link2_visual'>
          <pose frame=''>0 0 0 0 -0 0</pose>
          <geometry>
            <mesh>
              <scale>1 1 1</scale>
              <uri>/home/zjy/catkin_ws/src/wust_robot/wust_robot_description/meshes/R_Link2.STL</uri>
            </mesh>
          </geometry>
          <material>
            <script>
              <uri>file://media/materials/scripts/gazebo.material</uri>
              <name>Gazebo/FlatBlack</name>
            </script>
          </material>
        </visual>
        <gravity>1</gravity>
        <velocity_decay/>
        <self_collide>0</self_collide>
        <kinematic>0</kinematic>
      </link>
      <joint name='R_joint2' type='revolute'>
        <child>R_Link2</child>
        <parent>R_Link1</parent>
        <axis>
          <xyz>-0.866867 -0.49854 0</xyz>
          <limit>
            <lower>-2.09</lower>
            <upper>2.09</upper>
            <effort>90</effort>
            <velocity>1.31</velocity>
          </limit>
          <dynamics>
            <spring_reference>0</spring_reference>
            <spring_stiffness>0</spring_stiffness>
          </dynamics>
          <use_parent_model_frame>1</use_parent_model_frame>
        </axis>
      </joint>
      <link name='R_Link3'>
        <pose frame=''>-0.10043 -0.391988 1.16179 -0 -1.56231 2.09271</pose>
        <inertial>
          <pose frame=''>-0.000124 -0.016173 0.058519 0 -0 0</pose>
          <mass>0.174901</mass>
          <inertia>
            <ixx>0.000566838</ixx>
            <ixy>1.87641e-07</ixy>
            <ixz>4.09347e-07</ixz>
            <iyy>0.000579069</iyy>
            <iyz>3.49852e-05</iyz>
            <izz>0.00024042</izz>
          </inertia>
        </inertial>
        <collision name='R_Link3_collision'>
          <pose frame=''>0 0 0 0 -0 0</pose>
          <geometry>
            <mesh>
              <scale>1 1 1</scale>
              <uri>/home/zjy/catkin_ws/src/wust_robot/wust_robot_description/meshes/R_Link3.STL</uri>
            </mesh>
          </geometry>
          <surface>
            <contact>
              <ode/>
            </contact>
            <friction>
              <ode/>
              <torsional>
                <ode/>
              </torsional>
            </friction>
            <bounce/>
          </surface>
          <max_contacts>10</max_contacts>
        </collision>
        <visual name='R_Link3_visual'>
          <pose frame=''>0 0 0 0 -0 0</pose>
          <geometry>
            <mesh>
              <scale>1 1 1</scale>
              <uri>/home/zjy/catkin_ws/src/wust_robot/wust_robot_description/meshes/R_Link3.STL</uri>
            </mesh>
          </geometry>
          <material>
            <script>
              <uri>file://media/materials/scripts/gazebo.material</uri>
              <name>Gazebo/FlatBlack</name>
            </script>
          </material>
        </visual>
        <gravity>1</gravity>
        <velocity_decay/>
        <self_collide>0</self_collide>
        <kinematic>0</kinematic>
      </link>
      <joint name='R_joint3' type='revolute'>
        <child>R_Link3</child>
        <parent>R_Link2</parent>
        <axis>
          <xyz>-0.498525 0.866834 -0.008487</xyz>
          <limit>
            <lower>-3.05</lower>
            <upper>3.05</upper>
            <effort>67</effort>
            <velocity>1.31</velocity>
          </limit>
          <dynamics>
            <spring_reference>0</spring_reference>
            <spring_stiffness>0</spring_stiffness>
          </dynamics>
          <use_parent_model_frame>1</use_parent_model_frame>
        </axis>
      </joint>
      <link name='R_Link4'>
        <pose frame=''>-0.093013 -0.504573 1.16299 -1.5708 -1.56231 2.09271</pose>
        <inertial>
          <pose frame=''>0.000815 -0.06738 -0.022767 0 -0 0</pose>
          <mass>0.13914</mass>
          <inertia>
            <ixx>0.000567282</ixx>
            <ixy>4.50372e-06</ixy>
            <ixz>1.9065e-06</ixz>
            <iyy>0.000225917</iyy>
            <iyz>-0.000151211</iyz>
            <izz>0.000540283</izz>
          </inertia>
        </inertial>
        <collision name='R_Link4_collision'>
          <pose frame=''>0 0 0 0 -0 0</pose>
          <geometry>
            <mesh>
              <scale>1 1 1</scale>
              <uri>/home/zjy/catkin_ws/src/wust_robot/wust_robot_description/meshes/R_Link4.STL</uri>
            </mesh>
          </geometry>
          <surface>
            <contact>
              <ode/>
            </contact>
            <friction>
              <ode/>
              <torsional>
                <ode/>
              </torsional>
            </friction>
            <bounce/>
          </surface>
          <max_contacts>10</max_contacts>
        </collision>
        <visual name='R_Link4_visual'>
          <pose frame=''>0 0 0 0 -0 0</pose>
          <geometry>
            <mesh>
              <scale>1 1 1</scale>
              <uri>/home/zjy/catkin_ws/src/wust_robot/wust_robot_description/meshes/R_Link4.STL</uri>
            </mesh>
          </geometry>
          <material>
            <script>
              <uri>file://media/materials/scripts/gazebo.material</uri>
              <name>Gazebo/FlatBlack</name>
            </script>
          </material>
        </visual>
        <gravity>1</gravity>
        <velocity_decay/>
        <self_collide>0</self_collide>
        <kinematic>0</kinematic>
      </link>
      <joint name='R_joint4' type='revolute'>
        <child>R_Link4</child>
        <parent>R_Link3</parent>
        <axis>
          <xyz>-0.866867 -0.49854 0</xyz>
          <limit>
            <lower>-2.09</lower>
            <upper>2.09</upper>
            <effort>67</effort>
            <velocity>1.31</velocity>
          </limit>
          <dynamics>
            <spring_reference>0</spring_reference>
            <spring_stiffness>0</spring_stiffness>
          </dynamics>
          <use_parent_model_frame>1</use_parent_model_frame>
        </axis>
      </joint>
      <link name='R_Link5'>
        <pose frame=''>0.036899 -0.630773 1.16665 -0 -1.56231 2.09271</pose>
        <inertial>
          <pose frame=''>-8e-05 -0.012205 0.030908 0 -0 0</pose>
          <mass>0.0974187</mass>
          <inertia>
            <ixx>0.000193994</ixx>
            <ixy>-1.48441e-08</ixy>
            <ixz>1.92065e-07</ixz>
            <iyy>0.000192392</iyy>
            <iyz>2.59298e-05</iyz>
            <izz>0.000116052</izz>
          </inertia>
        </inertial>
        <collision name='R_Link5_collision'>
          <pose frame=''>0 0 0 0 -0 0</pose>
          <geometry>
            <mesh>
              <scale>1 1 1</scale>
              <uri>/home/zjy/catkin_ws/src/wust_robot/wust_robot_description/meshes/R_Link5.STL</uri>
            </mesh>
          </geometry>
          <surface>
            <contact>
              <ode/>
            </contact>
            <friction>
              <ode/>
              <torsional>
                <ode/>
              </torsional>
            </friction>
            <bounce/>
          </surface>
          <max_contacts>10</max_contacts>
        </collision>
        <visual name='R_Link5_visual'>
          <pose frame=''>0 0 0 0 -0 0</pose>
          <geometry>
            <mesh>
              <scale>1 1 1</scale>
              <uri>/home/zjy/catkin_ws/src/wust_robot/wust_robot_description/meshes/R_Link5.STL</uri>
            </mesh>
          </geometry>
          <material>
            <script>
              <uri>file://media/materials/scripts/gazebo.material</uri>
              <name>Gazebo/FlatBlack</name>
            </script>
          </material>
        </visual>
        <gravity>1</gravity>
        <velocity_decay/>
        <self_collide>0</self_collide>
        <kinematic>0</kinematic>
      </link>
      <joint name='R_joint5' type='revolute'>
        <child>R_Link5</child>
        <parent>R_Link4</parent>
        <axis>
          <xyz>-0.498525 0.866834 -0.008487</xyz>
          <limit>
            <lower>-3.05</lower>
            <upper>3.05</upper>
            <effort>67</effort>
            <velocity>1.57</velocity>
          </limit>
          <dynamics>
            <spring_reference>0</spring_reference>
            <spring_stiffness>0</spring_stiffness>
          </dynamics>
          <use_parent_model_frame>1</use_parent_model_frame>
        </axis>
      </joint>
      <link name='R_Link6'>
        <pose frame=''>0.040272 -0.707041 1.16747 -1.5708 -1.56231 2.09271</pose>
        <inertial>
          <pose frame=''>0.000577 -0.046301 -0.020592 0 -0 0</pose>
          <mass>0.0709944</mass>
          <inertia>
            <ixx>0.000150339</ixx>
            <ixy>9.85293e-07</ixy>
            <ixz>4.29279e-07</ixz>
            <iyy>6.97108e-05</iyy>
            <iyz>-3.53439e-05</iyz>
            <izz>0.000145966</izz>
          </inertia>
        </inertial>
        <collision name='R_Link6_collision'>
          <pose frame=''>0 0 0 0 -0 0</pose>
          <geometry>
            <mesh>
              <scale>1 1 1</scale>
              <uri>/home/zjy/catkin_ws/src/wust_robot/wust_robot_description/meshes/R_Link6.STL</uri>
            </mesh>
          </geometry>
          <surface>
            <contact>
              <ode/>
            </contact>
            <friction>
              <ode/>
              <torsional>
                <ode/>
              </torsional>
            </friction>
            <bounce/>
          </surface>
          <max_contacts>10</max_contacts>
        </collision>
        <visual name='R_Link6_visual'>
          <pose frame=''>0 0 0 0 -0 0</pose>
          <geometry>
            <mesh>
              <scale>1 1 1</scale>
              <uri>/home/zjy/catkin_ws/src/wust_robot/wust_robot_description/meshes/R_Link6.STL</uri>
            </mesh>
          </geometry>
          <material>
            <script>
              <uri>file://media/materials/scripts/gazebo.material</uri>
              <name>Gazebo/FlatBlack</name>
            </script>
          </material>
        </visual>
        <gravity>1</gravity>
        <velocity_decay/>
        <self_collide>0</self_collide>
        <kinematic>0</kinematic>
      </link>
      <joint name='R_joint6' type='revolute'>
        <child>R_Link6</child>
        <parent>R_Link5</parent>
        <axis>
          <xyz>-0.866867 -0.49854 0</xyz>
          <limit>
            <lower>-2.09</lower>
            <upper>2.09</upper>
            <effort>67</effort>
            <velocity>1.57</velocity>
          </limit>
          <dynamics>
            <spring_reference>0</spring_reference>
            <spring_stiffness>0</spring_stiffness>
          </dynamics>
          <use_parent_model_frame>1</use_parent_model_frame>
        </axis>
      </joint>
      <link name='R_Link7'>
        <pose frame=''>0.135046 -0.80143 1.17017 -0 -1.56231 2.09271</pose>
        <inertial>
          <pose frame=''>4.6e-05 1e-06 0.021461 0 -0 0</pose>
          <mass>0.069592</mass>
          <inertia>
            <ixx>0.000100578</ixx>
            <ixy>-8.86468e-08</ixy>
            <ixz>-5.47757e-08</ixz>
            <iyy>8.85998e-05</iyy>
            <iyz>6.35169e-09</iyz>
            <izz>8.88089e-05</izz>
          </inertia>
        </inertial>
        <collision name='R_Link7_collision'>
          <pose frame=''>0 0 0 0 -0 0</pose>
          <geometry>
            <mesh>
              <scale>1 1 1</scale>
              <uri>/home/zjy/catkin_ws/src/wust_robot/wust_robot_description/meshes/R_Link7.STL</uri>
            </mesh>
          </geometry>
          <surface>
            <contact>
              <ode>
                <kp>1e+08</kp>
                <kd>1</kd>
                <max_vel>1</max_vel>
                <min_depth>0.01</min_depth>
              </ode>
            </contact>
            <friction>
              <ode>
                <mu>200</mu>
                <mu2>200</mu2>
              </ode>
              <torsional>
                <ode/>
              </torsional>
            </friction>
            <bounce/>
          </surface>
          <max_contacts>10</max_contacts>
        </collision>
        <visual name='R_Link7_visual'>
          <pose frame=''>0 0 0 0 -0 0</pose>
          <geometry>
            <mesh>
              <scale>1 1 1</scale>
              <uri>/home/zjy/catkin_ws/src/wust_robot/wust_robot_description/meshes/R_Link7.STL</uri>
            </mesh>
          </geometry>
          <material>
            <ambient>0.792157 0.819608 0.933333 1</ambient>
            <diffuse>0.792157 0.819608 0.933333 1</diffuse>
            <specular>0.1 0.1 0.1 1</specular>
            <emissive>0 0 0 0</emissive>
            <script>
              <uri>__default__</uri>
              <name>__default__</name>
            </script>
          </material>
        </visual>
        <gravity>1</gravity>
        <velocity_decay/>
        <self_collide>0</self_collide>
        <kinematic>0</kinematic>
      </link>
      <joint name='R_joint7' type='revolute'>
        <child>R_Link7</child>
        <parent>R_Link6</parent>
        <axis>
          <xyz>-0.498525 0.866834 -0.008487</xyz>
          <limit>
            <lower>-3.05</lower>
            <upper>3.05</upper>
            <effort>33</effort>
            <velocity>1.57</velocity>
          </limit>
          <dynamics>
            <spring_reference>0</spring_reference>
            <spring_stiffness>0</spring_stiffness>
          </dynamics>
          <use_parent_model_frame>1</use_parent_model_frame>
        </axis>
      </joint>
      <link name='R_left_finger'>
        <pose frame=''>0.188432 -0.838096 1.17047 -0.001743 -0.010795 -1.57079</pose>
        <inertial>
          <pose frame=''>0.026096 0.026849 1.7e-05 0 -0 0</pose>
          <mass>0.0222032</mass>
          <inertia>
            <ixx>5.17634e-06</ixx>
            <ixy>-5.08077e-06</ixy>
            <ixz>3.86266e-09</ixz>
            <iyy>1.09633e-05</iyy>
            <iyz>-2.46942e-10</iyz>
            <izz>1.31832e-05</izz>
          </inertia>
        </inertial>
        <collision name='R_left_finger_collision'>
          <pose frame=''>0 0 0 0 -0 0</pose>
          <geometry>
            <mesh>
              <scale>1 1 1</scale>
              <uri>/home/zjy/catkin_ws/src/wust_robot/wust_robot_description/meshes/R_left_finger.STL</uri>
            </mesh>
          </geometry>
          <surface>
            <contact>
              <ode>
                <kp>1e+08</kp>
                <kd>1</kd>
                <max_vel>0.1</max_vel>
                <min_depth>0.01</min_depth>
              </ode>
            </contact>
            <friction>
              <ode>
                <mu>200</mu>
                <mu2>200</mu2>
              </ode>
              <torsional>
                <ode/>
              </torsional>
            </friction>
            <bounce/>
          </surface>
          <max_contacts>10</max_contacts>
        </collision>
        <visual name='R_left_finger_visual'>
          <pose frame=''>0 0 0 0 -0 0</pose>
          <geometry>
            <mesh>
              <scale>1 1 1</scale>
              <uri>/home/zjy/catkin_ws/src/wust_robot/wust_robot_description/meshes/R_left_finger.STL</uri>
            </mesh>
          </geometry>
          <material>
            <ambient>0.792157 0.819608 0.933333 1</ambient>
            <diffuse>0.792157 0.819608 0.933333 1</diffuse>
            <specular>0.1 0.1 0.1 1</specular>
            <emissive>0 0 0 0</emissive>
            <script>
              <uri>__default__</uri>
              <name>__default__</name>
            </script>
          </material>
        </visual>
        <gravity>1</gravity>
        <velocity_decay/>
        <self_collide>0</self_collide>
        <kinematic>0</kinematic>
      </link>
      <joint name='R_left_joint' type='revolute'>
        <child>R_left_finger</child>
        <parent>R_Link7</parent>
        <axis>
          <xyz>0.001743 0.010795 0.99994</xyz>
          <limit>
            <lower>-0.35</lower>
            <upper>0.35</upper>
            <effort>33</effort>
            <velocity>1.57</velocity>
          </limit>
          <dynamics>
            <spring_reference>0</spring_reference>
            <spring_stiffness>0</spring_stiffness>
          </dynamics>
          <use_parent_model_frame>1</use_parent_model_frame>
        </axis>
      </joint>
      <link name='R_right_finger'>
        <pose frame=''>0.139888 -0.866011 1.17086 -0.010803 0.001753 -1e-06</pose>
        <inertial>
          <pose frame=''>0.009007 -0.036187 -1.7e-05 0 -0 0</pose>
          <mass>0.0220975</mass>
          <inertia>
            <ixx>1.08406e-05</ixx>
            <ixy>5.1118e-06</ixy>
            <ixz>-3.55147e-09</ixz>
            <iyy>5.29285e-06</iyy>
            <iyz>1.38784e-09</iyz>
            <izz>1.31809e-05</izz>
          </inertia>
        </inertial>
        <collision name='R_right_finger_collision'>
          <pose frame=''>0 0 0 0 -0 0</pose>
          <geometry>
            <mesh>
              <scale>1 1 1</scale>
              <uri>/home/zjy/catkin_ws/src/wust_robot/wust_robot_description/meshes/R_right_finger.STL</uri>
            </mesh>
          </geometry>
          <surface>
            <contact>
              <ode>
                <kp>1e+08</kp>
                <kd>1</kd>
                <max_vel>0.1</max_vel>
                <min_depth>0.01</min_depth>
              </ode>
            </contact>
            <friction>
              <ode>
                <mu>200</mu>
                <mu2>200</mu2>
              </ode>
              <torsional>
                <ode/>
              </torsional>
            </friction>
            <bounce/>
          </surface>
          <max_contacts>10</max_contacts>
        </collision>
        <visual name='R_right_finger_visual'>
          <pose frame=''>0 0 0 0 -0 0</pose>
          <geometry>
            <mesh>
              <scale>1 1 1</scale>
              <uri>/home/zjy/catkin_ws/src/wust_robot/wust_robot_description/meshes/R_right_finger.STL</uri>
            </mesh>
          </geometry>
          <material>
            <ambient>0.792157 0.819608 0.933333 1</ambient>
            <diffuse>0.792157 0.819608 0.933333 1</diffuse>
            <specular>0.1 0.1 0.1 1</specular>
            <emissive>0 0 0 0</emissive>
            <script>
              <uri>__default__</uri>
              <name>__default__</name>
            </script>
          </material>
        </visual>
        <gravity>1</gravity>
        <velocity_decay/>
        <self_collide>0</self_collide>
        <kinematic>0</kinematic>
      </link>
      <joint name='R_right_joint' type='revolute'>
        <child>R_right_finger</child>
        <parent>R_Link7</parent>
        <axis>
          <xyz>0.001753 0.010803 0.99994</xyz>
          <limit>
            <lower>-0.35</lower>
            <upper>0.35</upper>
            <effort>33</effort>
            <velocity>1.57</velocity>
          </limit>
          <dynamics>
            <spring_reference>0</spring_reference>
            <spring_stiffness>0</spring_stiffness>
          </dynamics>
          <use_parent_model_frame>1</use_parent_model_frame>
        </axis>
      </joint>
      <link name='wheel_Link1'>
        <pose frame=''>-0.103621 0.316965 0.0402 1.5708 -0 2.61799</pose>
        <inertial>
          <pose frame=''>0 -0 -0.003202 0 -0 0</pose>
          <mass>0.784918</mass>
          <inertia>
            <ixx>0.00103508</ixx>
            <ixy>-1.20507e-09</ixy>
            <ixz>-1.4077e-11</ixz>
            <iyy>0.00103511</iyy>
            <iyz>-1.29208e-12</iyz>
            <izz>0.00137479</izz>
          </inertia>
        </inertial>
        <collision name='wheel_Link1_collision'>
          <pose frame=''>0 0 0 0 -0 0</pose>
          <geometry>
            <mesh>
              <scale>1 1 1</scale>
              <uri>/home/zjy/catkin_ws/src/wust_robot/wust_robot_description/meshes/wheel_Link1.STL</uri>
            </mesh>
          </geometry>
          <max_contacts>10</max_contacts>
          <surface>
            <contact>
              <ode/>
            </contact>
            <bounce/>
            <friction>
              <torsional>
                <ode/>
              </torsional>
              <ode/>
            </friction>
          </surface>
        </collision>
        <visual name='wheel_Link1_visual'>
          <pose frame=''>0 0 0 0 -0 0</pose>
          <geometry>
            <mesh>
              <scale>1 1 1</scale>
              <uri>/home/zjy/catkin_ws/src/wust_robot/wust_robot_description/meshes/wheel_Link1.STL</uri>
            </mesh>
          </geometry>
        </visual>
        <self_collide>0</self_collide>
        <kinematic>0</kinematic>
        <gravity>1</gravity>
      </link>
      <joint name='wheel_joint1' type='revolute'>
        <child>wheel_Link1</child>
        <parent>base_dummy</parent>
        <axis>
          <xyz>0.5 0.866025 0</xyz>
          <limit>
            <lower>-1e+16</lower>
            <upper>1e+16</upper>
          </limit>
          <dynamics>
            <spring_reference>0</spring_reference>
            <spring_stiffness>0</spring_stiffness>
          </dynamics>
          <use_parent_model_frame>1</use_parent_model_frame>
        </axis>
      </joint>
      <link name='wheel_Link2'>
        <pose frame=''>-0.652621 0 0.0402 1.5708 0 -1.5708</pose>
        <inertial>
          <pose frame=''>0 -0 -0.003202 0 -0 0</pose>
          <mass>0.784918</mass>
          <inertia>
            <ixx>0.00103508</ixx>
            <ixy>-2.85682e-09</ixy>
            <ixz>1.18111e-13</ixz>
            <iyy>0.00103511</iyy>
            <iyz>-6.67149e-12</iyz>
            <izz>0.00137479</izz>
          </inertia>
        </inertial>
        <collision name='wheel_Link2_collision'>
          <pose frame=''>0 0 0 0 -0 0</pose>
          <geometry>
            <mesh>
              <scale>1 1 1</scale>
              <uri>/home/zjy/catkin_ws/src/wust_robot/wust_robot_description/meshes/wheel_Link2.STL</uri>
            </mesh>
          </geometry>
          <max_contacts>10</max_contacts>
          <surface>
            <contact>
              <ode/>
            </contact>
            <bounce/>
            <friction>
              <torsional>
                <ode/>
              </torsional>
              <ode/>
            </friction>
          </surface>
        </collision>
        <visual name='wheel_Link2_visual'>
          <pose frame=''>0 0 0 0 -0 0</pose>
          <geometry>
            <mesh>
              <scale>1 1 1</scale>
              <uri>/home/zjy/catkin_ws/src/wust_robot/wust_robot_description/meshes/wheel_Link2.STL</uri>
            </mesh>
          </geometry>
        </visual>
        <self_collide>0</self_collide>
        <kinematic>0</kinematic>
        <gravity>1</gravity>
      </link>
      <joint name='wheel_joint2' type='revolute'>
        <child>wheel_Link2</child>
        <parent>base_dummy</parent>
        <axis>
          <xyz>-1 0 0</xyz>
          <limit>
            <lower>-1e+16</lower>
            <upper>1e+16</upper>
          </limit>
          <dynamics>
            <spring_reference>0</spring_reference>
            <spring_stiffness>0</spring_stiffness>
          </dynamics>
          <use_parent_model_frame>1</use_parent_model_frame>
        </axis>
      </joint>
      <link name='wheel_Link3'>
        <pose frame=''>-0.103621 -0.316965 0.0402 1.5708 -0 0.523599</pose>
        <inertial>
          <pose frame=''>-0 -0 -0.003202 0 -0 0</pose>
          <mass>0.784918</mass>
          <inertia>
            <ixx>0.00103508</ixx>
            <ixy>-8.54797e-10</ixy>
            <ixz>9.34219e-12</ixz>
            <iyy>0.00103511</iyy>
            <iyz>-1.46548e-13</iyz>
            <izz>0.00137479</izz>
          </inertia>
        </inertial>
        <collision name='wheel_Link3_collision'>
          <pose frame=''>0 0 0 0 -0 0</pose>
          <geometry>
            <mesh>
              <scale>1 1 1</scale>
              <uri>/home/zjy/catkin_ws/src/wust_robot/wust_robot_description/meshes/wheel_Link3.STL</uri>
            </mesh>
          </geometry>
          <max_contacts>10</max_contacts>
          <surface>
            <contact>
              <ode/>
            </contact>
            <bounce/>
            <friction>
              <torsional>
                <ode/>
              </torsional>
              <ode/>
            </friction>
          </surface>
        </collision>
        <visual name='wheel_Link3_visual'>
          <pose frame=''>0 0 0 0 -0 0</pose>
          <geometry>
            <mesh>
              <scale>1 1 1</scale>
              <uri>/home/zjy/catkin_ws/src/wust_robot/wust_robot_description/meshes/wheel_Link3.STL</uri>
            </mesh>
          </geometry>
        </visual>
        <self_collide>0</self_collide>
        <kinematic>0</kinematic>
        <gravity>1</gravity>
      </link>
      <joint name='wheel_joint3' type='revolute'>
        <child>wheel_Link3</child>
        <parent>base_dummy</parent>
        <axis>
          <xyz>-0.5 0.866025 0</xyz>
          <limit>
            <lower>-1e+16</lower>
            <upper>1e+16</upper>
          </limit>
          <dynamics>
            <spring_reference>0</spring_reference>
            <spring_stiffness>0</spring_stiffness>
          </dynamics>
          <use_parent_model_frame>1</use_parent_model_frame>
        </axis>
      </joint>
      <plugin name='gazebo_ros_control' filename='libgazebo_ros_control.so'>
        <robotNamespace>/wust_robot</robotNamespace>
        <robotSimType>gazebo_ros_control/DefaultRobotHWSim</robotSimType>
        <legacyModeNS>true</legacyModeNS>
      </plugin>
      <plugin name='gazebo_grasp_fix_1eft' filename='libgazebo_grasp_fix.so'>
        <arm>
          <arm_name>left_arm</arm_name>
          <palm_link>L_Link7</palm_link>
          <gripper_link>L_left_finger</gripper_link>
          <gripper_link>L_right_finger</gripper_link>
        </arm>
        <arm>
          <arm_name>right_arm</arm_name>
          <palm_link>R_Link7</palm_link>
          <gripper_link>R_left_finger</gripper_link>
          <gripper_link>R_right_finger</gripper_link>
        </arm>
        <forces_angle_tolerance>100</forces_angle_tolerance>
        <update_rate>4</update_rate>
        <grip_count_threshold>4</grip_count_threshold>
        <max_grip_count>8</max_grip_count>
        <release_tolerance>0.003</release_tolerance>
        <disable_collisions_on_attach>false</disable_collisions_on_attach>
        <contact_topic>__default_topic__</contact_topic>
        <robotNamespace>/</robotNamespace>
      </plugin>
      <static>0</static>
      <plugin name='mpo_500_controller' filename='libgazebo_ros_planar_move.so'>
        <commandTopic>cmd_vel</commandTopic>
        <leftFrontJoint>wheel_joint1</leftFrontJoint>
        <rightFrontJoint>wheel_joint2</rightFrontJoint>
        <leftRearJoint>wheel_joint3</leftRearJoint>
        <odometryTopic>odom</odometryTopic>
        <odometryFrame>odom</odometryFrame>
        <odometryRate>20.0</odometryRate>
        <robotBaseFrame>base_dummy</robotBaseFrame>
        <robotNamespace>/</robotNamespace>
      </plugin>
      <pose frame=''>0 0 0 0 -0 0</pose>
    </model>
    <model name='bottle1_1'>
      <link name='link_0'>
        <pose frame=''>0 0 0 0 -0 0</pose>
        <inertial>
          <mass>0.2</mass>
          <inertia>
            <ixx>0.166667</ixx>
            <ixy>0</ixy>
            <ixz>0</ixz>
            <iyy>0.166667</iyy>
            <iyz>0</iyz>
            <izz>0.166667</izz>
          </inertia>
          <pose frame=''>0 0 0 0 -0 0</pose>
        </inertial>
        <self_collide>0</self_collide>
        <kinematic>0</kinematic>
        <gravity>1</gravity>
        <visual name='visual'>
          <pose frame=''>0 0 0 0 -0 0</pose>
          <geometry>
            <mesh>
              <uri>/home/zjy/catkin_ws/src/models/bottle1/meshes/bottle1.STL</uri>
              <scale>1 1 1</scale>
            </mesh>
          </geometry>
          <material>
            <lighting>1</lighting>
            <script>
              <uri>file://media/materials/scripts/gazebo.material</uri>
              <name>Gazebo/Grey</name>
            </script>
            <ambient>0.3 0.3 0.3 1</ambient>
            <diffuse>0.7 0.7 0.7 1</diffuse>
            <specular>0.01 0.01 0.01 1</specular>
            <emissive>0 0 0 1</emissive>
            <shader type='vertex'>
              <normal_map>__default__</normal_map>
            </shader>
          </material>
          <cast_shadows>1</cast_shadows>
          <transparency>0</transparency>
        </visual>
        <collision name='collision'>
          <laser_retro>0</laser_retro>
          <max_contacts>10</max_contacts>
          <pose frame=''>0 0 0 0 -0 0</pose>
          <geometry>
            <mesh>
              <uri>/home/zjy/catkin_ws/src/models/bottle1/meshes/bottle1.STL</uri>
              <scale>1 1 1</scale>
            </mesh>
          </geometry>
          <surface>
            <friction>
              <ode>
                <mu>1</mu>
                <mu2>1</mu2>
                <fdir1>0 0 0</fdir1>
                <slip1>0</slip1>
                <slip2>0</slip2>
              </ode>
              <torsional>
                <coefficient>1</coefficient>
                <patch_radius>0</patch_radius>
                <surface_radius>0</surface_radius>
                <use_patch_radius>1</use_patch_radius>
                <ode>
                  <slip>0</slip>
                </ode>
              </torsional>
            </friction>
            <bounce>
              <restitution_coefficient>0</restitution_coefficient>
              <threshold>1e+06</threshold>
            </bounce>
            <contact>
              <collide_without_contact>0</collide_without_contact>
              <collide_without_contact_bitmask>1</collide_without_contact_bitmask>
              <collide_bitmask>1</collide_bitmask>
              <ode>
                <soft_cfm>0</soft_cfm>
                <soft_erp>0.2</soft_erp>
                <kp>1e+13</kp>
                <kd>1</kd>
                <max_vel>0.01</max_vel>
                <min_depth>0</min_depth>
              </ode>
              <bullet>
                <split_impulse>1</split_impulse>
                <split_impulse_penetration_threshold>-0.01</split_impulse_penetration_threshold>
                <soft_cfm>0</soft_cfm>
                <soft_erp>0.2</soft_erp>
                <kp>1e+13</kp>
                <kd>1</kd>
              </bullet>
            </contact>
          </surface>
        </collision>
      </link>
      <static>0</static>
      <allow_auto_disable>1</allow_auto_disable>
      <pose frame=''>0.45 -0.300061 0.901449 1.57167 -0 0</pose>
    </model>
    <model name='bottle2_0'>
      <link name='link_0'>
        <pose frame=''>0 0 0 0 -0 0</pose>
        <inertial>
          <mass>0.1</mass>
          <inertia>
            <ixx>0.02</ixx>
            <ixy>0</ixy>
            <ixz>0</ixz>
            <iyy>0.0166667</iyy>
            <iyz>0</iyz>
            <izz>0.0166667</izz>
          </inertia>
          <pose frame=''>0 0 0 0 -0 0</pose>
        </inertial>
        <self_collide>0</self_collide>
        <kinematic>0</kinematic>
        <gravity>1</gravity>
        <visual name='visual'>
          <pose frame=''>0 0 0 0 -0 0</pose>
          <geometry>
            <mesh>
              <uri>/home/zjy/catkin_ws/src/models/bottle2/meshes/bottle2.STL</uri>
              <scale>1 1 1</scale>
            </mesh>
          </geometry>
          <material>
            <lighting>1</lighting>
            <script>
              <uri>file://media/materials/scripts/gazebo.material</uri>
              <name>Gazebo/Grey</name>
            </script>
            <ambient>0.3 0.3 0.3 1</ambient>
            <diffuse>0.7 0.7 0.7 1</diffuse>
            <specular>0.01 0.01 0.01 1</specular>
            <emissive>0 0 0 1</emissive>
            <shader type='vertex'>
              <normal_map>__default__</normal_map>
            </shader>
          </material>
          <cast_shadows>1</cast_shadows>
          <transparency>0</transparency>
        </visual>
        <collision name='collision'>
          <laser_retro>0</laser_retro>
          <max_contacts>10</max_contacts>
          <pose frame=''>0 0 0 0 -0 0</pose>
          <geometry>
            <mesh>
              <uri>/home/zjy/catkin_ws/src/models/bottle2/meshes/bottle2.STL</uri>
              <scale>1 1 1</scale>
            </mesh>
          </geometry>
          <surface>
            <friction>
              <ode>
                <mu>1</mu>
                <mu2>1</mu2>
                <fdir1>0 0 0</fdir1>
                <slip1>0</slip1>
                <slip2>0</slip2>
              </ode>
              <torsional>
                <coefficient>1</coefficient>
                <patch_radius>0</patch_radius>
                <surface_radius>0</surface_radius>
                <use_patch_radius>1</use_patch_radius>
                <ode>
                  <slip>0</slip>
                </ode>
              </torsional>
            </friction>
            <bounce>
              <restitution_coefficient>0</restitution_coefficient>
              <threshold>1e+06</threshold>
            </bounce>
            <contact>
              <collide_without_contact>0</collide_without_contact>
              <collide_without_contact_bitmask>1</collide_without_contact_bitmask>
              <collide_bitmask>1</collide_bitmask>
              <ode>
                <soft_cfm>0</soft_cfm>
                <soft_erp>0.2</soft_erp>
                <kp>1e+13</kp>
                <kd>1</kd>
                <max_vel>0.01</max_vel>
                <min_depth>0</min_depth>
              </ode>
              <bullet>
                <split_impulse>1</split_impulse>
                <split_impulse_penetration_threshold>-0.01</split_impulse_penetration_threshold>
                <soft_cfm>0</soft_cfm>
                <soft_erp>0.2</soft_erp>
                <kp>1e+13</kp>
                <kd>1</kd>
              </bullet>
            </contact>
          </surface>
        </collision>
      </link>
      <static>0</static>
      <allow_auto_disable>1</allow_auto_disable>
      <pose frame=''>0.45 0.3 0.897387 1.57077 -3.6e-05 -0</pose>
    </model>
    <model name='table_model'>
      <link name='table_top_link'>
        <pose frame=''>0 0 0 0 -0 0</pose>
        <inertial>
          <pose frame=''>0.8 0 0.535 0 -0 0</pose>
          <mass>50</mass>
          <inertia>
            <ixx>92.845</ixx>
            <ixy>0</ixy>
            <ixz>0</ixz>
            <iyy>12.845</iyy>
            <iyz>0</iyz>
            <izz>101.04</izz>
          </inertia>
        </inertial>
        <collision name='table_top_link_collision'>
          <pose frame=''>0.8 0 0.875 0 -0 0</pose>
          <geometry>
            <box>
              <size>1 3 0.05</size>
            </box>
          </geometry>
          <surface>
            <contact>
              <ode>
                <kp>1e+06</kp>
                <kd>1</kd>
              </ode>
            </contact>
            <friction>
              <ode>
                <mu>50</mu>
                <mu2>50</mu2>
              </ode>
              <torsional>
                <ode/>
              </torsional>
            </friction>
            <bounce/>
          </surface>
          <max_contacts>10</max_contacts>
        </collision>
        <collision name='table_top_link_fixed_joint_lump__leg1_link_collision_1'>
          <pose frame=''>1.3 1.5 0.45 0 -0 0</pose>
          <geometry>
            <cylinder>
              <length>0.9</length>
              <radius>0.02</radius>
            </cylinder>
          </geometry>
          <surface>
            <contact>
              <ode>
                <kp>1e+07</kp>
                <kd>1</kd>
              </ode>
            </contact>
            <friction>
              <ode>
                <mu>1000</mu>
                <mu2>1000</mu2>
              </ode>
              <torsional>
                <ode/>
              </torsional>
            </friction>
            <bounce/>
          </surface>
          <max_contacts>10</max_contacts>
        </collision>
        <collision name='table_top_link_fixed_joint_lump__leg2_link_collision_2'>
          <pose frame=''>0.3 1.5 0.45 0 -0 0</pose>
          <geometry>
            <cylinder>
              <length>0.9</length>
              <radius>0.02</radius>
            </cylinder>
          </geometry>
          <surface>
            <contact>
              <ode>
                <kp>1e+07</kp>
                <kd>1</kd>
              </ode>
            </contact>
            <friction>
              <ode>
                <mu>1000</mu>
                <mu2>1000</mu2>
              </ode>
              <torsional>
                <ode/>
              </torsional>
            </friction>
            <bounce/>
          </surface>
          <max_contacts>10</max_contacts>
        </collision>
        <collision name='table_top_link_fixed_joint_lump__leg3_link_collision_3'>
          <pose frame=''>1.3 -1.5 0.45 0 -0 0</pose>
          <geometry>
            <cylinder>
              <length>0.9</length>
              <radius>0.02</radius>
            </cylinder>
          </geometry>
          <surface>
            <contact>
              <ode>
                <kp>1e+07</kp>
                <kd>1</kd>
              </ode>
            </contact>
            <friction>
              <ode>
                <mu>1000</mu>
                <mu2>1000</mu2>
              </ode>
              <torsional>
                <ode/>
              </torsional>
            </friction>
            <bounce/>
          </surface>
          <max_contacts>10</max_contacts>
        </collision>
        <collision name='table_top_link_fixed_joint_lump__leg4_link_collision_4'>
          <pose frame=''>0.3 -1.5 0.45 0 -0 0</pose>
          <geometry>
            <cylinder>
              <length>0.9</length>
              <radius>0.02</radius>
            </cylinder>
          </geometry>
          <surface>
            <contact>
              <ode>
                <kp>1e+07</kp>
                <kd>1</kd>
              </ode>
            </contact>
            <friction>
              <ode>
                <mu>1000</mu>
                <mu2>1000</mu2>
              </ode>
              <torsional>
                <ode/>
              </torsional>
            </friction>
            <bounce/>
          </surface>
          <max_contacts>10</max_contacts>
        </collision>
        <visual name='table_top_link_visual'>
          <pose frame=''>0.8 0 0.875 0 -0 0</pose>
          <geometry>
            <box>
              <size>1 3 0.05</size>
            </box>
          </geometry>
          <material>
            <script>
              <name>Gazebo/Wood</name>
              <uri>file://media/materials/scripts/gazebo.material</uri>
            </script>
          </material>
        </visual>
        <visual name='table_top_link_fixed_joint_lump__leg1_link_visual_1'>
          <pose frame=''>1.3 1.5 0.45 0 -0 0</pose>
          <geometry>
            <cylinder>
              <length>0.9</length>
              <radius>0.02</radius>
            </cylinder>
          </geometry>
          <material>
            <script>
              <name>Gazebo/Red</name>
              <uri>file://media/materials/scripts/gazebo.material</uri>
            </script>
          </material>
        </visual>
        <visual name='table_top_link_fixed_joint_lump__leg2_link_visual_2'>
          <pose frame=''>0.3 1.5 0.45 0 -0 0</pose>
          <geometry>
            <cylinder>
              <length>0.9</length>
              <radius>0.02</radius>
            </cylinder>
          </geometry>
          <material>
            <script>
              <name>Gazebo/Red</name>
              <uri>file://media/materials/scripts/gazebo.material</uri>
            </script>
          </material>
        </visual>
        <visual name='table_top_link_fixed_joint_lump__leg3_link_visual_3'>
          <pose frame=''>1.3 -1.5 0.45 0 -0 0</pose>
          <geometry>
            <cylinder>
              <length>0.9</length>
              <radius>0.02</radius>
            </cylinder>
          </geometry>
          <material>
            <script>
              <name>Gazebo/Red</name>
              <uri>file://media/materials/scripts/gazebo.material</uri>
            </script>
          </material>
        </visual>
        <visual name='table_top_link_fixed_joint_lump__leg4_link_visual_4'>
          <pose frame=''>0.3 -1.5 0.45 0 -0 0</pose>
          <geometry>
            <cylinder>
              <length>0.9</length>
              <radius>0.02</radius>
            </cylinder>
          </geometry>
          <material>
            <script>
              <name>Gazebo/Red</name>
              <uri>file://media/materials/scripts/gazebo.material</uri>
            </script>
          </material>
        </visual>
        <velocity_decay/>
        <velocity_decay/>
        <velocity_decay/>
        <velocity_decay/>
        <gravity>1</gravity>
        <velocity_decay/>
        <self_collide>1</self_collide>
        <kinematic>0</kinematic>
      </link>
      <static>1</static>
      <pose frame=''>0 0 0.01 0 -0 0</pose>
    </model>
    <model name='pallet_1'>
      <link name='link_0'>
        <pose frame=''>0 0 0 0 -0 0</pose>
        <inertial>
          <mass>1</mass>
          <inertia>
            <ixx>0.166667</ixx>
            <ixy>0</ixy>
            <ixz>0</ixz>
            <iyy>0.166667</iyy>
            <iyz>0</iyz>
            <izz>0.166667</izz>
          </inertia>
          <pose frame=''>0 0 0 0 -0 0</pose>
        </inertial>
        <self_collide>0</self_collide>
        <kinematic>0</kinematic>
        <gravity>1</gravity>
        <visual name='visual'>
          <pose frame=''>0 0 0 0 -0 0</pose>
          <geometry>
            <mesh>
              <uri>/home/zjy/catkin_ws/src/models/pallet/meshes/pallet.STL</uri>
              <scale>1 1 1</scale>
            </mesh>
          </geometry>
          <material>
            <lighting>1</lighting>
            <script>
              <uri>file://media/materials/scripts/gazebo.material</uri>
              <name>Gazebo/Wood</name>
            </script>
            <ambient>0.3 0.3 0.3 1</ambient>
            <diffuse>0.7 0.7 0.7 1</diffuse>
            <specular>0.01 0.01 0.01 1</specular>
            <emissive>0 0 0 1</emissive>
            <shader type='vertex'>
              <normal_map>__default__</normal_map>
            </shader>
          </material>
          <cast_shadows>1</cast_shadows>
          <transparency>0</transparency>
        </visual>
        <collision name='collision'>
          <laser_retro>0</laser_retro>
          <max_contacts>10</max_contacts>
          <pose frame=''>0 0 0 0 -0 0</pose>
          <geometry>
            <mesh>
              <uri>/home/zjy/catkin_ws/src/models/pallet/meshes/pallet.STL</uri>
              <scale>1 1 1</scale>
            </mesh>
          </geometry>
          <surface>
            <friction>
              <ode>
                <mu>1</mu>
                <mu2>1</mu2>
                <fdir1>0 0 0</fdir1>
                <slip1>0</slip1>
                <slip2>0</slip2>
              </ode>
              <torsional>
                <coefficient>1</coefficient>
                <patch_radius>0</patch_radius>
                <surface_radius>0</surface_radius>
                <use_patch_radius>1</use_patch_radius>
                <ode>
                  <slip>0</slip>
                </ode>
              </torsional>
            </friction>
            <bounce>
              <restitution_coefficient>0</restitution_coefficient>
              <threshold>1e+06</threshold>
            </bounce>
            <contact>
              <collide_without_contact>0</collide_without_contact>
              <collide_without_contact_bitmask>1</collide_without_contact_bitmask>
              <collide_bitmask>1</collide_bitmask>
              <ode>
                <soft_cfm>0</soft_cfm>
                <soft_erp>0.2</soft_erp>
                <kp>1e+13</kp>
                <kd>1</kd>
                <max_vel>0.01</max_vel>
                <min_depth>0</min_depth>
              </ode>
              <bullet>
                <split_impulse>1</split_impulse>
                <split_impulse_penetration_threshold>-0.01</split_impulse_penetration_threshold>
                <soft_cfm>0</soft_cfm>
                <soft_erp>0.2</soft_erp>
                <kp>1e+13</kp>
                <kd>1</kd>
              </bullet>
            </contact>
          </surface>
        </collision>
      </link>
      <static>0</static>
      <allow_auto_disable>1</allow_auto_disable>
      <pose frame=''>0.449999 1.5 0.899996 1.57078 1e-06 -1.57174</pose>
    </model>
  </world>
</sdf>
