<sdf version='1.6'>
  <world name='default'>
    <light name='sun' type='directional'>
      <cast_shadows>1</cast_shadows>
      <pose frame=''>0 0 10 0 -0 0</pose>
      <diffuse>0.8 0.8 0.8 1</diffuse>
      <specular>0.1 0.1 0.1 1</specular>
      <attenuation>
        <range>1000</range>
        <constant>0.9</constant>
        <linear>0.01</linear>
        <quadratic>0.001</quadratic>
      </attenuation>
      <direction>-0.5 0.5 -1</direction>
    </light>
    <model name='ground_plane'>
      <static>1</static>
      <link name='link'>
        <collision name='collision'>
          <geometry>
            <plane>
              <normal>0 0 1</normal>
              <size>100 100</size>
            </plane>
          </geometry>
          <surface>
            <friction>
              <ode>
                <mu>100</mu>
                <mu2>50</mu2>
              </ode>
              <torsional>
                <ode/>
              </torsional>
            </friction>
            <contact>
              <ode/>
            </contact>
            <bounce/>
          </surface>
          <max_contacts>10</max_contacts>
        </collision>
        <visual name='visual'>
          <cast_shadows>0</cast_shadows>
          <geometry>
            <plane>
              <normal>0 0 1</normal>
              <size>100 100</size>
            </plane>
          </geometry>
          <material>
            <script>
              <uri>file://media/materials/scripts/gazebo.material</uri>
              <name>Gazebo/Grey</name>
            </script>
          </material>
        </visual>
        <self_collide>0</self_collide>
        <kinematic>0</kinematic>
        <gravity>1</gravity>
      </link>
    </model>
    <gravity>0 0 -9.8</gravity>
    <magnetic_field>6e-06 2.3e-05 -4.2e-05</magnetic_field>
    <atmosphere type='adiabatic'/>
    <physics name='default_physics' default='0' type='ode'>
      <max_step_size>0.001</max_step_size>
      <real_time_factor>1</real_time_factor>
      <real_time_update_rate>1000</real_time_update_rate>
    </physics>
    <scene>
      <ambient>0.4 0.4 0.4 1</ambient>
      <background>0.7 0.7 0.7 1</background>
      <shadows>1</shadows>
    </scene>
    <spherical_coordinates>
      <surface_model>EARTH_WGS84</surface_model>
      <latitude_deg>0</latitude_deg>
      <longitude_deg>0</longitude_deg>
      <elevation>0</elevation>
      <heading_deg>0</heading_deg>
    </spherical_coordinates>
    <model name='wust_robot'>
      <link name='base_dummy'>
        <pose frame=''>0 0 0 0 -0 0</pose>
        <inertial>
          <pose frame=''>-0.256089 -0.004553 0.473508 0 -0 0</pose>
          <mass>104.133</mass>
          <inertia>
            <ixx>27.5778</ixx>
            <ixy>-0.00723216</ixy>
            <ixz>-1.66262</ixz>
            <iyy>25.9707</iyy>
            <iyz>0.0320579</iyz>
            <izz>8.15858</izz>
          </inertia>
        </inertial>
        <collision name='base_dummy_fixed_joint_lump__base_link_collision'>
          <pose frame=''>0 0 0 0 -0 0</pose>
          <geometry>
            <mesh>
              <scale>1 1 1</scale>
              <uri>/home/zjy/catkin_ws/src/wust_robot/wust_robot_description/meshes/base_link.STL</uri>
            </mesh>
          </geometry>
          <surface>
            <contact>
              <ode/>
            </contact>
            <friction>
              <ode/>
              <torsional>
                <ode/>
              </torsional>
            </friction>
            <bounce/>
          </surface>
          <max_contacts>10</max_contacts>
        </collision>
        <collision name='base_dummy_fixed_joint_lump__L_Link0_collision_1'>
          <pose frame=''>-0.277217 0.076447 1.1543 3.14159 1.56054 -2.09613</pose>
          <geometry>
            <mesh>
              <scale>1 1 1</scale>
              <uri>/home/zjy/catkin_ws/src/wust_robot/wust_robot_description/meshes/L_Link0.STL</uri>
            </mesh>
          </geometry>
          <surface>
            <contact>
              <ode/>
            </contact>
            <friction>
              <ode/>
              <torsional>
                <ode/>
              </torsional>
            </friction>
            <bounce/>
          </surface>
          <max_contacts>10</max_contacts>
        </collision>
        <collision name='base_dummy_fixed_joint_lump__R_Link0_collision_2'>
          <pose frame=''>-0.282475 -0.075449 1.15595 -0 -1.56231 2.09271</pose>
          <geometry>
            <mesh>
              <scale>1 1 1</scale>
              <uri>/home/zjy/catkin_ws/src/wust_robot/wust_robot_description/meshes/R_Link0.STL</uri>
            </mesh>
          </geometry>
          <surface>
            <contact>
              <ode/>
            </contact>
            <friction>
              <ode/>
              <torsional>
                <ode/>
              </torsional>
            </friction>
            <bounce/>
          </surface>
          <max_contacts>10</max_contacts>
        </collision>
        <collision name='base_dummy_fixed_joint_lump__camera_link_collision_3'>
          <pose frame=''>0.3 0 0.7 3.14159 1.57079 3.14159</pose>
          <geometry>
            <mesh>
              <scale>1 1 1</scale>
              <uri>/home/zjy/catkin_ws/src/wust_robot/wust_robot_description/meshes/camera.STL</uri>
            </mesh>
          </geometry>
          <surface>
            <contact>
              <ode/>
            </contact>
            <friction>
              <ode/>
              <torsional>
                <ode/>
              </torsional>
            </friction>
            <bounce/>
          </surface>
          <max_contacts>10</max_contacts>
        </collision>
        <visual name='base_dummy_fixed_joint_lump__base_link_visual'>
          <pose frame=''>0 0 0 0 -0 0</pose>
          <geometry>
            <mesh>
              <scale>1 1 1</scale>
              <uri>/home/zjy/catkin_ws/src/wust_robot/wust_robot_description/meshes/base_link.STL</uri>
            </mesh>
          </geometry>
          <material>
            <script>
              <uri>file://media/materials/scripts/gazebo.material</uri>
              <name>Gazebo/Grey</name>
            </script>
          </material>
        </visual>
        <visual name='base_dummy_fixed_joint_lump__L_Link0_visual_1'>
          <pose frame=''>-0.277217 0.076447 1.1543 3.14159 1.56054 -2.09613</pose>
          <geometry>
            <mesh>
              <scale>1 1 1</scale>
              <uri>/home/zjy/catkin_ws/src/wust_robot/wust_robot_description/meshes/L_Link0.STL</uri>
            </mesh>
          </geometry>
          <material>
            <ambient>0.792157 0.819608 0.933333 1</ambient>
            <diffuse>0.792157 0.819608 0.933333 1</diffuse>
            <specular>0.1 0.1 0.1 1</specular>
            <emissive>0 0 0 0</emissive>
            <script>
              <uri>__default__</uri>
              <name>__default__</name>
            </script>
          </material>
        </visual>
        <visual name='base_dummy_fixed_joint_lump__R_Link0_visual_2'>
          <pose frame=''>-0.282475 -0.075449 1.15595 -0 -1.56231 2.09271</pose>
          <geometry>
            <mesh>
              <scale>1 1 1</scale>
              <uri>/home/zjy/catkin_ws/src/wust_robot/wust_robot_description/meshes/R_Link0.STL</uri>
            </mesh>
          </geometry>
          <material>
            <ambient>0.792157 0.819608 0.933333 1</ambient>
            <diffuse>0.792157 0.819608 0.933333 1</diffuse>
            <specular>0.1 0.1 0.1 1</specular>
            <emissive>0 0 0 0</emissive>
            <script>
              <uri>__default__</uri>
              <name>__default__</name>
            </script>
          </material>
        </visual>
        <visual name='base_dummy_fixed_joint_lump__camera_link_visual_3'>
          <pose frame=''>0.299363 0 1.5 -3.14 0.000796 -1.5708</pose>
          <geometry>
            <mesh>
              <scale>1 1 1</scale>
              <uri>/home/zjy/catkin_ws/src/wust_robot/wust_robot_description/meshes/camera.STL</uri>
            </mesh>
          </geometry>
          <material>
            <script>
              <name>Gazebo/Red</name>
              <uri>file://media/materials/scripts/gazebo.material</uri>
            </script>
          </material>
        </visual>
        <velocity_decay/>
        <velocity_decay/>
        <velocity_decay/>
        <gravity>1</gravity>
        <velocity_decay/>
        <self_collide>0</self_collide>
        <sensor name='camera' type='camera'>
          <update_rate>30</update_rate>
          <camera name='head'>
            <horizontal_fov>1.3</horizontal_fov>
            <image>
              <width>800</width>
              <height>800</height>
              <format>R8G8B8</format>
            </image>
            <clip>
              <near>0.02</near>
              <far>300</far>
            </clip>
            <noise>
              <type>gaussian</type>
              <mean>0</mean>
              <stddev>0.007</stddev>
            </noise>
          </camera>
          <plugin name='camera_controller' filename='libgazebo_ros_camera.so'>
            <alwaysOn>true</alwaysOn>
            <updateRate>0.0</updateRate>
            <cameraName>wust_robot/camera</cameraName>
            <imageTopicName>image_raw</imageTopicName>
            <cameraInfoTopicName>camera_info</cameraInfoTopicName>
            <frameName>camera_link</frameName>
            <hackBaseline>0.07</hackBaseline>
            <distortionK1>0.0</distortionK1>
            <distortionK2>0.0</distortionK2>
            <distortionK3>0.0</distortionK3>
            <distortionT1>0.0</distortionT1>
            <distortionT2>0.0</distortionT2>
            <robotNamespace>/</robotNamespace>
          </plugin>
          <pose frame=''>0.3 0 0.7 3.14159 1.57079 3.14159</pose>
        </sensor>
        <kinematic>0</kinematic>
      </link>
      <link name='L_Link1'>
        <pose frame=''>-0.248382 0.126191 1.15371 -3.14073 1.56054 -2.09526</pose>
        <inertial>
          <pose frame=''>-4e-05 -0.015653 0.060113 0 -0 0</pose>
          <mass>0.225999</mass>
          <inertia>
            <ixx>0.000855101</ixx>
            <ixy>1.28543e-07</ixy>
            <ixz>6.24869e-07</ixz>
            <iyy>0.000896246</iyy>
            <iyz>6.58583e-05</iyz>
            <izz>0.000416139</izz>
          </inertia>
        </inertial>
        <collision name='L_Link1_collision'>
          <pose frame=''>0 0 0 0 -0 0</pose>
          <geometry>
            <mesh>
              <scale>1 1 1</scale>
              <uri>/home/zjy/catkin_ws/src/wust_robot/wust_robot_description/meshes/L_Link1.STL</uri>
            </mesh>
          </geometry>
          <surface>
            <contact>
              <ode/>
            </contact>
            <friction>
              <ode/>
              <torsional>
                <ode/>
              </torsional>
            </friction>
            <bounce/>
          </surface>
          <max_contacts>10</max_contacts>
        </collision>
        <visual name='L_Link1_visual'>
          <pose frame=''>0 0 0 0 -0 0</pose>
          <geometry>
            <mesh>
              <scale>1 1 1</scale>
              <uri>/home/zjy/catkin_ws/src/wust_robot/wust_robot_description/meshes/L_Link1.STL</uri>
            </mesh>
          </geometry>
          <material>
            <script>
              <uri>file://media/materials/scripts/gazebo.material</uri>
              <name>Gazebo/FlatBlack</name>
            </script>
          </material>
        </visual>
        <gravity>1</gravity>
        <velocity_decay/>
        <self_collide>0</self_collide>
        <kinematic>0</kinematic>
      </link>
      <joint name='L_joint1' type='revolute'>
        <child>L_Link1</child>
        <parent>base_dummy</parent>
        <axis>
          <xyz>0.501472 0.865113 -0.010255</xyz>
          <limit>
            <lower>-3.05</lower>
            <upper>3.05</upper>
            <effort>90</effort>
            <velocity>1.31</velocity>
          </limit>
          <dynamics>
            <spring_reference>0</spring_reference>
            <spring_stiffness>0</spring_stiffness>
          </dynamics>
          <use_parent_model_frame>1</use_parent_model_frame>
        </axis>
      </joint>
      <link name='L_Link2'>
        <pose frame=''>-0.239714 0.244834 1.15241 1.57166 1.56054 -2.09526</pose>
        <inertial>
          <pose frame=''>0.000857 -0.068856 -0.021948 0 -0 0</pose>
          <mass>0.211155</mass>
          <inertia>
            <ixx>0.000996806</ixx>
            <ixy>7.35505e-06</ixy>
            <ixz>3.3042e-06</ixz>
            <iyy>0.000405577</iyy>
            <iyz>-0.000263492</iyz>
            <izz>0.000942075</izz>
          </inertia>
        </inertial>
        <collision name='L_Link2_collision'>
          <pose frame=''>0 0 0 0 -0 0</pose>
          <geometry>
            <mesh>
              <scale>1 1 1</scale>
              <uri>/home/zjy/catkin_ws/src/wust_robot/wust_robot_description/meshes/L_Link2.STL</uri>
            </mesh>
          </geometry>
          <surface>
            <contact>
              <ode/>
            </contact>
            <friction>
              <ode/>
              <torsional>
                <ode/>
              </torsional>
            </friction>
            <bounce/>
          </surface>
          <max_contacts>10</max_contacts>
        </collision>
        <visual name='L_Link2_visual'>
          <pose frame=''>0 0 0 0 -0 0</pose>
          <geometry>
            <mesh>
              <scale>1 1 1</scale>
              <uri>/home/zjy/catkin_ws/src/wust_robot/wust_robot_description/meshes/L_Link2.STL</uri>
            </mesh>
          </geometry>
          <material>
            <script>
              <uri>file://media/materials/scripts/gazebo.material</uri>
              <name>Gazebo/FlatBlack</name>
            </script>
          </material>
        </visual>
        <gravity>1</gravity>
        <velocity_decay/>
        <self_collide>0</self_collide>
        <kinematic>0</kinematic>
      </link>
      <joint name='L_joint2' type='revolute'>
        <child>L_Link2</child>
        <parent>L_Link1</parent>
        <axis>
          <xyz>-0.865161 0.501495 -9e-06</xyz>
          <limit>
            <lower>-2.09</lower>
            <upper>2.09</upper>
            <effort>90</effort>
            <velocity>1.31</velocity>
          </limit>
          <dynamics>
            <spring_reference>0</spring_reference>
            <spring_stiffness>0</spring_stiffness>
          </dynamics>
          <use_parent_model_frame>1</use_parent_model_frame>
        </axis>
      </joint>
      <link name='L_Link3'>
        <pose frame=''>-0.099122 0.383693 1.14764 -3.14073 1.56054 -2.09526</pose>
        <inertial>
          <pose frame=''>-0.000502 -0.016173 0.058519 0 -0 0</pose>
          <mass>0.174901</mass>
          <inertia>
            <ixx>0.000566836</ixx>
            <ixy>1.50177e-07</ixy>
            <ixz>3.02203e-07</ixz>
            <iyy>0.000579069</iyy>
            <iyz>3.49865e-05</iyz>
            <izz>0.00024042</izz>
          </inertia>
        </inertial>
        <collision name='L_Link3_collision'>
          <pose frame=''>0 0 0 0 -0 0</pose>
          <geometry>
            <mesh>
              <scale>1 1 1</scale>
              <uri>/home/zjy/catkin_ws/src/wust_robot/wust_robot_description/meshes/L_Link3.STL</uri>
            </mesh>
          </geometry>
          <surface>
            <contact>
              <ode/>
            </contact>
            <friction>
              <ode/>
              <torsional>
                <ode/>
              </torsional>
            </friction>
            <bounce/>
          </surface>
          <max_contacts>10</max_contacts>
        </collision>
        <visual name='L_Link3_visual'>
          <pose frame=''>0 0 0 0 -0 0</pose>
          <geometry>
            <mesh>
              <scale>1 1 1</scale>
              <uri>/home/zjy/catkin_ws/src/wust_robot/wust_robot_description/meshes/L_Link3.STL</uri>
            </mesh>
          </geometry>
          <material>
            <script>
              <uri>file://media/materials/scripts/gazebo.material</uri>
              <name>Gazebo/FlatBlack</name>
            </script>
          </material>
        </visual>
        <gravity>1</gravity>
        <velocity_decay/>
        <self_collide>0</self_collide>
        <kinematic>0</kinematic>
      </link>
      <joint name='L_joint3' type='revolute'>
        <child>L_Link3</child>
        <parent>L_Link2</parent>
        <axis>
          <xyz>0.501472 0.865113 -0.010255</xyz>
          <limit>
            <lower>-3.05</lower>
            <upper>3.05</upper>
            <effort>67</effort>
            <velocity>1.31</velocity>
          </limit>
          <dynamics>
            <spring_reference>0</spring_reference>
            <spring_stiffness>0</spring_stiffness>
          </dynamics>
          <use_parent_model_frame>1</use_parent_model_frame>
        </axis>
      </joint>
      <link name='L_Link4'>
        <pose frame=''>-0.09132 0.496255 1.14684 1.57166 1.56054 -2.09526</pose>
        <inertial>
          <pose frame=''>0.000816 -0.067379 -0.022767 0 -0 0</pose>
          <mass>0.139141</mass>
          <inertia>
            <ixx>0.000567296</ixx>
            <ixy>4.51474e-06</ixy>
            <ixz>1.91083e-06</ixz>
            <iyy>0.000225919</iyy>
            <iyz>-0.000151217</iyz>
            <izz>0.000540296</izz>
          </inertia>
        </inertial>
        <collision name='L_Link4_collision'>
          <pose frame=''>0 0 0 0 -0 0</pose>
          <geometry>
            <mesh>
              <scale>1 1 1</scale>
              <uri>/home/zjy/catkin_ws/src/wust_robot/wust_robot_description/meshes/L_Link4.STL</uri>
            </mesh>
          </geometry>
          <surface>
            <contact>
              <ode/>
            </contact>
            <friction>
              <ode/>
              <torsional>
                <ode/>
              </torsional>
            </friction>
            <bounce/>
          </surface>
          <max_contacts>10</max_contacts>
        </collision>
        <visual name='L_Link4_visual'>
          <pose frame=''>0 0 0 0 -0 0</pose>
          <geometry>
            <mesh>
              <scale>1 1 1</scale>
              <uri>/home/zjy/catkin_ws/src/wust_robot/wust_robot_description/meshes/L_Link4.STL</uri>
            </mesh>
          </geometry>
          <material>
            <script>
              <uri>file://media/materials/scripts/gazebo.material</uri>
              <name>Gazebo/FlatBlack</name>
            </script>
          </material>
        </visual>
        <gravity>1</gravity>
        <velocity_decay/>
        <self_collide>0</self_collide>
        <kinematic>0</kinematic>
      </link>
      <joint name='L_joint4' type='revolute'>
        <child>L_Link4</child>
        <parent>L_Link3</parent>
        <axis>
          <xyz>-0.865161 0.501495 -9e-06</xyz>
          <limit>
            <lower>-2.09</lower>
            <upper>2.09</upper>
            <effort>67</effort>
            <velocity>1.31</velocity>
          </limit>
          <dynamics>
            <spring_reference>0</spring_reference>
            <spring_stiffness>0</spring_stiffness>
          </dynamics>
          <use_parent_model_frame>1</use_parent_model_frame>
        </axis>
      </joint>
      <link name='L_Link5'>
        <pose frame=''>0.039018 0.622006 1.14287 -3.14073 1.56054 -2.09526</pose>
        <inertial>
          <pose frame=''>-4.3e-05 -0.012206 0.030908 0 -0 0</pose>
          <mass>0.0974186</mass>
          <inertia>
            <ixx>0.000193994</ixx>
            <ixy>-1.08151e-08</ixy>
            <ixz>1.12866e-07</ixz>
            <iyy>0.000192392</iyy>
            <iyz>2.593e-05</iyz>
            <izz>0.000116052</izz>
          </inertia>
        </inertial>
        <collision name='L_Link5_collision'>
          <pose frame=''>0 0 0 0 -0 0</pose>
          <geometry>
            <mesh>
              <scale>1 1 1</scale>
              <uri>/home/zjy/catkin_ws/src/wust_robot/wust_robot_description/meshes/L_Link5.STL</uri>
            </mesh>
          </geometry>
          <surface>
            <contact>
              <ode/>
            </contact>
            <friction>
              <ode/>
              <torsional>
                <ode/>
              </torsional>
            </friction>
            <bounce/>
          </surface>
          <max_contacts>10</max_contacts>
        </collision>
        <visual name='L_Link5_visual'>
          <pose frame=''>0 0 0 0 -0 0</pose>
          <geometry>
            <mesh>
              <scale>1 1 1</scale>
              <uri>/home/zjy/catkin_ws/src/wust_robot/wust_robot_description/meshes/L_Link5.STL</uri>
            </mesh>
          </geometry>
          <material>
            <script>
              <uri>file://media/materials/scripts/gazebo.material</uri>
              <name>Gazebo/FlatBlack</name>
            </script>
          </material>
        </visual>
        <gravity>1</gravity>
        <velocity_decay/>
        <self_collide>0</self_collide>
        <kinematic>0</kinematic>
      </link>
      <joint name='L_joint5' type='revolute'>
        <child>L_Link5</child>
        <parent>L_Link4</parent>
        <axis>
          <xyz>0.501472 0.865113 -0.010255</xyz>
          <limit>
            <lower>-3.05</lower>
            <upper>3.05</upper>
            <effort>67</effort>
            <velocity>1.57</velocity>
          </limit>
          <dynamics>
            <spring_reference>0</spring_reference>
            <spring_stiffness>0</spring_stiffness>
          </dynamics>
          <use_parent_model_frame>1</use_parent_model_frame>
        </axis>
      </joint>
      <link name='L_Link6'>
        <pose frame=''>0.04265 0.698262 1.14204 1.57166 1.56054 -2.09526</pose>
        <inertial>
          <pose frame=''>0.000578 -0.046301 -0.020592 0 -0 0</pose>
          <mass>0.0709946</mass>
          <inertia>
            <ixx>0.00015034</ixx>
            <ixy>9.87376e-07</ixy>
            <ixz>4.30166e-07</ixz>
            <iyy>6.97108e-05</iyy>
            <iyz>-3.5344e-05</iyz>
            <izz>0.000145966</izz>
          </inertia>
        </inertial>
        <collision name='L_Link6_collision'>
          <pose frame=''>0 0 0 0 -0 0</pose>
          <geometry>
            <mesh>
              <scale>1 1 1</scale>
              <uri>/home/zjy/catkin_ws/src/wust_robot/wust_robot_description/meshes/L_Link6.STL</uri>
            </mesh>
          </geometry>
          <surface>
            <contact>
              <ode/>
            </contact>
            <friction>
              <ode/>
              <torsional>
                <ode/>
              </torsional>
            </friction>
            <bounce/>
          </surface>
          <max_contacts>10</max_contacts>
        </collision>
        <visual name='L_Link6_visual'>
          <pose frame=''>0 0 0 0 -0 0</pose>
          <geometry>
            <mesh>
              <scale>1 1 1</scale>
              <uri>/home/zjy/catkin_ws/src/wust_robot/wust_robot_description/meshes/L_Link6.STL</uri>
            </mesh>
          </geometry>
          <material>
            <script>
              <uri>file://media/materials/scripts/gazebo.material</uri>
              <name>Gazebo/FlatBlack</name>
            </script>
          </material>
        </visual>
        <gravity>1</gravity>
        <velocity_decay/>
        <self_collide>0</self_collide>
        <kinematic>0</kinematic>
      </link>
      <joint name='L_joint6' type='revolute'>
        <child>L_Link6</child>
        <parent>L_Link5</parent>
        <axis>
          <xyz>-0.865161 0.501495 -9e-06</xyz>
          <limit>
            <lower>-2.09</lower>
            <upper>2.09</upper>
            <effort>67</effort>
            <velocity>1.57</velocity>
          </limit>
          <dynamics>
            <spring_reference>0</spring_reference>
            <spring_stiffness>0</spring_stiffness>
          </dynamics>
          <use_parent_model_frame>1</use_parent_model_frame>
        </axis>
      </joint>
      <link name='L_Link7'>
        <pose frame=''>0.137744 0.792323 1.1391 -3.14073 1.56054 -2.09526</pose>
        <inertial>
          <pose frame=''>4.6e-05 1e-06 0.021461 0 -0 0</pose>
          <mass>0.0695915</mass>
          <inertia>
            <ixx>0.000100578</ixx>
            <ixy>-5.19959e-08</ixy>
            <ixz>-5.45712e-08</ixz>
            <iyy>8.8599e-05</iyy>
            <iyz>6.1563e-09</iyz>
            <izz>8.88087e-05</izz>
          </inertia>
        </inertial>
        <collision name='L_Link7_collision'>
          <pose frame=''>0 0 0 0 -0 0</pose>
          <geometry>
            <mesh>
              <scale>1 1 1</scale>
              <uri>/home/zjy/catkin_ws/src/wust_robot/wust_robot_description/meshes/L_Link7.STL</uri>
            </mesh>
          </geometry>
          <surface>
            <contact>
              <ode>
                <kp>1e+08</kp>
                <kd>1</kd>
                <max_vel>0.1</max_vel>
                <min_depth>0.01</min_depth>
              </ode>
            </contact>
            <friction>
              <ode>
                <mu>200</mu>
                <mu2>200</mu2>
              </ode>
              <torsional>
                <ode/>
              </torsional>
            </friction>
            <bounce/>
          </surface>
          <max_contacts>10</max_contacts>
        </collision>
        <visual name='L_Link7_visual'>
          <pose frame=''>0 0 0 0 -0 0</pose>
          <geometry>
            <mesh>
              <scale>1 1 1</scale>
              <uri>/home/zjy/catkin_ws/src/wust_robot/wust_robot_description/meshes/L_Link7.STL</uri>
            </mesh>
          </geometry>
          <material>
            <ambient>0.792157 0.819608 0.933333 1</ambient>
            <diffuse>0.792157 0.819608 0.933333 1</diffuse>
            <specular>0.1 0.1 0.1 1</specular>
            <emissive>0 0 0 0</emissive>
            <script>
              <uri>__default__</uri>
              <name>__default__</name>
            </script>
          </material>
        </visual>
        <gravity>1</gravity>
        <velocity_decay/>
        <self_collide>0</self_collide>
        <kinematic>0</kinematic>
      </link>
      <joint name='L_joint7' type='revolute'>
        <child>L_Link7</child>
        <parent>L_Link6</parent>
        <axis>
          <xyz>0.501472 0.865113 -0.010255</xyz>
          <limit>
            <lower>-3.05</lower>
            <upper>3.05</upper>
            <effort>33</effort>
            <velocity>1.57</velocity>
          </limit>
          <dynamics>
            <spring_reference>0</spring_reference>
            <spring_stiffness>0</spring_stiffness>
          </dynamics>
          <use_parent_model_frame>1</use_parent_model_frame>
        </axis>
      </joint>
      <link name='L_left_finger'>
        <pose frame=''>0.142805 0.856886 1.1384 -0.006415 0.008904 0.785362</pose>
        <inertial>
          <pose frame=''>0.03203 0.019158 1.7e-05 0 -0 0</pose>
          <mass>0.0222031</mass>
          <inertia>
            <ixx>2.94895e-06</ixx>
            <ixy>-2.74026e-06</ixy>
            <ixz>3.48999e-09</ixz>
            <iyy>1.31997e-05</iyy>
            <iyz>-1.52394e-09</iyz>
            <izz>1.31922e-05</izz>
          </inertia>
        </inertial>
        <collision name='L_left_finger_collision'>
          <pose frame=''>0 0 0 0 -0 0</pose>
          <geometry>
            <mesh>
              <scale>1 1 1</scale>
              <uri>/home/zjy/catkin_ws/src/wust_robot/wust_robot_description/meshes/L_left_finger.STL</uri>
            </mesh>
          </geometry>
          <surface>
            <contact>
              <ode>
                <kp>1e+08</kp>
                <kd>1</kd>
                <max_vel>0.1</max_vel>
                <min_depth>0.01</min_depth>
              </ode>
            </contact>
            <friction>
              <ode>
                <mu>200</mu>
                <mu2>200</mu2>
              </ode>
              <torsional>
                <ode/>
              </torsional>
            </friction>
            <bounce/>
          </surface>
          <max_contacts>10</max_contacts>
        </collision>
        <visual name='L_left_finger_visual'>
          <pose frame=''>0 0 0 0 -0 0</pose>
          <geometry>
            <mesh>
              <scale>1 1 1</scale>
              <uri>/home/zjy/catkin_ws/src/wust_robot/wust_robot_description/meshes/L_left_finger.STL</uri>
            </mesh>
          </geometry>
          <material>
            <ambient>0.792157 0.819608 0.933333 1</ambient>
            <diffuse>0.792157 0.819608 0.933333 1</diffuse>
            <specular>0.1 0.1 0.1 1</specular>
            <emissive>0 0 0 0</emissive>
            <script>
              <uri>__default__</uri>
              <name>__default__</name>
            </script>
          </material>
        </visual>
        <gravity>1</gravity>
        <velocity_decay/>
        <self_collide>0</self_collide>
        <kinematic>0</kinematic>
      </link>
      <joint name='L_left_joint' type='revolute'>
        <child>L_left_finger</child>
        <parent>L_Link7</parent>
        <axis>
          <xyz>0.001761 0.010832 0.99994</xyz>
          <limit>
            <lower>-0.36</lower>
            <upper>0.36</upper>
            <effort>33</effort>
            <velocity>1.57</velocity>
          </limit>
          <dynamics>
            <spring_reference>0</spring_reference>
            <spring_stiffness>0</spring_stiffness>
          </dynamics>
          <use_parent_model_frame>1</use_parent_model_frame>
        </axis>
      </joint>
      <link name='L_right_finger'>
        <pose frame=''>0.191255 0.828804 1.13861 -0.006415 0.008904 0.785362</pose>
        <inertial>
          <pose frame=''>0.037435 -0.000661 -1.7e-05 0 -0 0</pose>
          <mass>0.0222032</mass>
          <inertia>
            <ixx>2.96928e-06</ixx>
            <ixy>-2.85847e-06</ixy>
            <ixz>-2.56669e-09</ixz>
            <iyy>1.31704e-05</iyy>
            <iyz>-2.89707e-09</iyz>
            <izz>1.31832e-05</izz>
          </inertia>
        </inertial>
        <collision name='L_right_finger_collision'>
          <pose frame=''>0 0 0 0 -0 0</pose>
          <geometry>
            <mesh>
              <scale>1 1 1</scale>
              <uri>/home/zjy/catkin_ws/src/wust_robot/wust_robot_description/meshes/L_right_finger.STL</uri>
            </mesh>
          </geometry>
          <surface>
            <contact>
              <ode>
                <kp>1e+08</kp>
                <kd>1</kd>
                <max_vel>0.1</max_vel>
                <min_depth>0.01</min_depth>
              </ode>
            </contact>
            <friction>
              <ode>
                <mu>200</mu>
                <mu2>200</mu2>
              </ode>
              <torsional>
                <ode/>
              </torsional>
            </friction>
            <bounce/>
          </surface>
          <max_contacts>10</max_contacts>
        </collision>
        <visual name='L_right_finger_visual'>
          <pose frame=''>0 0 0 0 -0 0</pose>
          <geometry>
            <mesh>
              <scale>1 1 1</scale>
              <uri>/home/zjy/catkin_ws/src/wust_robot/wust_robot_description/meshes/L_right_finger.STL</uri>
            </mesh>
          </geometry>
          <material>
            <ambient>0.792157 0.819608 0.933333 1</ambient>
            <diffuse>0.792157 0.819608 0.933333 1</diffuse>
            <specular>0.1 0.1 0.1 1</specular>
            <emissive>0 0 0 0</emissive>
            <script>
              <uri>__default__</uri>
              <name>__default__</name>
            </script>
          </material>
        </visual>
        <gravity>1</gravity>
        <velocity_decay/>
        <self_collide>0</self_collide>
        <kinematic>0</kinematic>
      </link>
      <joint name='L_right_joint' type='revolute'>
        <child>L_right_finger</child>
        <parent>L_Link7</parent>
        <axis>
          <xyz>0.001761 0.010832 0.99994</xyz>
          <limit>
            <lower>-0.36</lower>
            <upper>0.36</upper>
            <effort>33</effort>
            <velocity>1.57</velocity>
          </limit>
          <dynamics>
            <spring_reference>0</spring_reference>
            <spring_stiffness>0</spring_stiffness>
          </dynamics>
          <use_parent_model_frame>1</use_parent_model_frame>
        </axis>
      </joint>
      <link name='R_Link1'>
        <pose frame=''>-0.248825 -0.13396 1.15652 -0 -1.56231 2.09271</pose>
        <inertial>
          <pose frame=''>-8.8e-05 -0.015652 0.060116 0 -0 0</pose>
          <mass>0.225989</mass>
          <inertia>
            <ixx>0.000855056</ixx>
            <ixy>2.56077e-07</ixy>
            <ixz>8.2956e-07</ixz>
            <iyy>0.000896207</iyy>
            <iyz>6.58679e-05</iyz>
            <izz>0.000416131</izz>
          </inertia>
        </inertial>
        <collision name='R_Link1_collision'>
          <pose frame=''>0 0 0 0 -0 0</pose>
          <geometry>
            <mesh>
              <scale>1 1 1</scale>
              <uri>/home/zjy/catkin_ws/src/wust_robot/wust_robot_description/meshes/R_Link1.STL</uri>
            </mesh>
          </geometry>
          <surface>
            <contact>
              <ode/>
            </contact>
            <friction>
              <ode/>
              <torsional>
                <ode/>
              </torsional>
            </friction>
            <bounce/>
          </surface>
          <max_contacts>10</max_contacts>
        </collision>
        <visual name='R_Link1_visual'>
          <pose frame=''>0 0 0 0 -0 0</pose>
          <geometry>
            <mesh>
              <scale>1 1 1</scale>
              <uri>/home/zjy/catkin_ws/src/wust_robot/wust_robot_description/meshes/R_Link1.STL</uri>
            </mesh>
          </geometry>
          <material>
            <script>
              <uri>file://media/materials/scripts/gazebo.material</uri>
              <name>Gazebo/FlatBlack</name>
            </script>
          </material>
        </visual>
        <gravity>1</gravity>
        <velocity_decay/>
        <self_collide>0</self_collide>
        <kinematic>0</kinematic>
      </link>
      <joint name='R_joint1' type='revolute'>
        <child>R_Link1</child>
        <parent>base_dummy</parent>
        <axis>
          <xyz>-0.498525 0.866834 -0.008487</xyz>
          <limit>
            <lower>-3.05</lower>
            <upper>3.05</upper>
            <effort>90</effort>
            <velocity>1.31</velocity>
          </limit>
          <dynamics>
            <spring_reference>0</spring_reference>
            <spring_stiffness>0</spring_stiffness>
          </dynamics>
          <use_parent_model_frame>1</use_parent_model_frame>
        </axis>
      </joint>
      <link name='R_Link2'>
        <pose frame=''>-0.24056 -0.252632 1.15779 -1.5708 -1.56231 2.09271</pose>
        <inertial>
          <pose frame=''>0.000855 -0.068856 -0.021948 0 -0 0</pose>
          <mass>0.211155</mass>
          <inertia>
            <ixx>0.000996807</ixx>
            <ixy>7.34047e-06</ixy>
            <ixz>3.29819e-06</ixz>
            <iyy>0.000405577</iyy>
            <iyz>-0.000263492</iyz>
            <izz>0.000942076</izz>
          </inertia>
        </inertial>
        <collision name='R_Link2_collision'>
          <pose frame=''>0 0 0 0 -0 0</pose>
          <geometry>
            <mesh>
              <scale>1 1 1</scale>
              <uri>/home/zjy/catkin_ws/src/wust_robot/wust_robot_description/meshes/R_Link2.STL</uri>
            </mesh>
          </geometry>
          <surface>
            <contact>
              <ode/>
            </contact>
            <friction>
              <ode/>
              <torsional>
                <ode/>
              </torsional>
            </friction>
            <bounce/>
          </surface>
          <max_contacts>10</max_contacts>
        </collision>
        <visual name='R_Link2_visual'>
          <pose frame=''>0 0 0 0 -0 0</pose>
          <geometry>
            <mesh>
              <scale>1 1 1</scale>
              <uri>/home/zjy/catkin_ws/src/wust_robot/wust_robot_description/meshes/R_Link2.STL</uri>
            </mesh>
          </geometry>
          <material>
            <script>
              <uri>file://media/materials/scripts/gazebo.material</uri>
              <name>Gazebo/FlatBlack</name>
            </script>
          </material>
        </visual>
        <gravity>1</gravity>
        <velocity_decay/>
        <self_collide>0</self_collide>
        <kinematic>0</kinematic>
      </link>
      <joint name='R_joint2' type='revolute'>
        <child>R_Link2</child>
        <parent>R_Link1</parent>
        <axis>
          <xyz>-0.866867 -0.49854 0</xyz>
          <limit>
            <lower>-2.09</lower>
            <upper>2.09</upper>
            <effort>90</effort>
            <velocity>1.31</velocity>
          </limit>
          <dynamics>
            <spring_reference>0</spring_reference>
            <spring_stiffness>0</spring_stiffness>
          </dynamics>
          <use_parent_model_frame>1</use_parent_model_frame>
        </axis>
      </joint>
      <link name='R_Link3'>
        <pose frame=''>-0.10043 -0.391988 1.16179 -0 -1.56231 2.09271</pose>
        <inertial>
          <pose frame=''>-0.000124 -0.016173 0.058519 0 -0 0</pose>
          <mass>0.174901</mass>
          <inertia>
            <ixx>0.000566838</ixx>
            <ixy>1.87641e-07</ixy>
            <ixz>4.09347e-07</ixz>
            <iyy>0.000579069</iyy>
            <iyz>3.49852e-05</iyz>
            <izz>0.00024042</izz>
          </inertia>
        </inertial>
        <collision name='R_Link3_collision'>
          <pose frame=''>0 0 0 0 -0 0</pose>
          <geometry>
            <mesh>
              <scale>1 1 1</scale>
              <uri>/home/zjy/catkin_ws/src/wust_robot/wust_robot_description/meshes/R_Link3.STL</uri>
            </mesh>
          </geometry>
          <surface>
            <contact>
              <ode/>
            </contact>
            <friction>
              <ode/>
              <torsional>
                <ode/>
              </torsional>
            </friction>
            <bounce/>
          </surface>
          <max_contacts>10</max_contacts>
        </collision>
        <visual name='R_Link3_visual'>
          <pose frame=''>0 0 0 0 -0 0</pose>
          <geometry>
            <mesh>
              <scale>1 1 1</scale>
              <uri>/home/zjy/catkin_ws/src/wust_robot/wust_robot_description/meshes/R_Link3.STL</uri>
            </mesh>
          </geometry>
          <material>
            <script>
              <uri>file://media/materials/scripts/gazebo.material</uri>
              <name>Gazebo/FlatBlack</name>
            </script>
          </material>
        </visual>
        <gravity>1</gravity>
        <velocity_decay/>
        <self_collide>0</self_collide>
        <kinematic>0</kinematic>
      </link>
      <joint name='R_joint3' type='revolute'>
        <child>R_Link3</child>
        <parent>R_Link2</parent>
        <axis>
          <xyz>-0.498525 0.866834 -0.008487</xyz>
          <limit>
            <lower>-3.05</lower>
            <upper>3.05</upper>
            <effort>67</effort>
            <velocity>1.31</velocity>
          </limit>
          <dynamics>
            <spring_reference>0</spring_reference>
            <spring_stiffness>0</spring_stiffness>
          </dynamics>
          <use_parent_model_frame>1</use_parent_model_frame>
        </axis>
      </joint>
      <link name='R_Link4'>
        <pose frame=''>-0.093013 -0.504573 1.16299 -1.5708 -1.56231 2.09271</pose>
        <inertial>
          <pose frame=''>0.000815 -0.06738 -0.022767 0 -0 0</pose>
          <mass>0.13914</mass>
          <inertia>
            <ixx>0.000567282</ixx>
            <ixy>4.50372e-06</ixy>
            <ixz>1.9065e-06</ixz>
            <iyy>0.000225917</iyy>
            <iyz>-0.000151211</iyz>
            <izz>0.000540283</izz>
          </inertia>
        </inertial>
        <collision name='R_Link4_collision'>
          <pose frame=''>0 0 0 0 -0 0</pose>
          <geometry>
            <mesh>
              <scale>1 1 1</scale>
              <uri>/home/zjy/catkin_ws/src/wust_robot/wust_robot_description/meshes/R_Link4.STL</uri>
            </mesh>
          </geometry>
          <surface>
            <contact>
              <ode/>
            </contact>
            <friction>
              <ode/>
              <torsional>
                <ode/>
              </torsional>
            </friction>
            <bounce/>
          </surface>
          <max_contacts>10</max_contacts>
        </collision>
        <visual name='R_Link4_visual'>
          <pose frame=''>0 0 0 0 -0 0</pose>
          <geometry>
            <mesh>
              <scale>1 1 1</scale>
              <uri>/home/zjy/catkin_ws/src/wust_robot/wust_robot_description/meshes/R_Link4.STL</uri>
            </mesh>
          </geometry>
          <material>
            <script>
              <uri>file://media/materials/scripts/gazebo.material</uri>
              <name>Gazebo/FlatBlack</name>
            </script>
          </material>
        </visual>
        <gravity>1</gravity>
        <velocity_decay/>
        <self_collide>0</self_collide>
        <kinematic>0</kinematic>
      </link>
      <joint name='R_joint4' type='revolute'>
        <child>R_Link4</child>
        <parent>R_Link3</parent>
        <axis>
          <xyz>-0.866867 -0.49854 0</xyz>
          <limit>
            <lower>-2.09</lower>
            <upper>2.09</upper>
            <effort>67</effort>
            <velocity>1.31</velocity>
          </limit>
          <dynamics>
            <spring_reference>0</spring_reference>
            <spring_stiffness>0</spring_stiffness>
          </dynamics>
          <use_parent_model_frame>1</use_parent_model_frame>
        </axis>
      </joint>
      <link name='R_Link5'>
        <pose frame=''>0.036899 -0.630773 1.16665 -0 -1.56231 2.09271</pose>
        <inertial>
          <pose frame=''>-8e-05 -0.012205 0.030908 0 -0 0</pose>
          <mass>0.0974187</mass>
          <inertia>
            <ixx>0.000193994</ixx>
            <ixy>-1.48441e-08</ixy>
            <ixz>1.92065e-07</ixz>
            <iyy>0.000192392</iyy>
            <iyz>2.59298e-05</iyz>
            <izz>0.000116052</izz>
          </inertia>
        </inertial>
        <collision name='R_Link5_collision'>
          <pose frame=''>0 0 0 0 -0 0</pose>
          <geometry>
            <mesh>
              <scale>1 1 1</scale>
              <uri>/home/zjy/catkin_ws/src/wust_robot/wust_robot_description/meshes/R_Link5.STL</uri>
            </mesh>
          </geometry>
          <surface>
            <contact>
              <ode/>
            </contact>
            <friction>
              <ode/>
              <torsional>
                <ode/>
              </torsional>
            </friction>
            <bounce/>
          </surface>
          <max_contacts>10</max_contacts>
        </collision>
        <visual name='R_Link5_visual'>
          <pose frame=''>0 0 0 0 -0 0</pose>
          <geometry>
            <mesh>
              <scale>1 1 1</scale>
              <uri>/home/zjy/catkin_ws/src/wust_robot/wust_robot_description/meshes/R_Link5.STL</uri>
            </mesh>
          </geometry>
          <material>
            <script>
              <uri>file://media/materials/scripts/gazebo.material</uri>
              <name>Gazebo/FlatBlack</name>
            </script>
          </material>
        </visual>
        <gravity>1</gravity>
        <velocity_decay/>
        <self_collide>0</self_collide>
        <kinematic>0</kinematic>
      </link>
      <joint name='R_joint5' type='revolute'>
        <child>R_Link5</child>
        <parent>R_Link4</parent>
        <axis>
          <xyz>-0.498525 0.866834 -0.008487</xyz>
          <limit>
            <lower>-3.05</lower>
            <upper>3.05</upper>
            <effort>67</effort>
            <velocity>1.57</velocity>
          </limit>
          <dynamics>
            <spring_reference>0</spring_reference>
            <spring_stiffness>0</spring_stiffness>
          </dynamics>
          <use_parent_model_frame>1</use_parent_model_frame>
        </axis>
      </joint>
      <link name='R_Link6'>
        <pose frame=''>0.040272 -0.707041 1.16747 -1.5708 -1.56231 2.09271</pose>
        <inertial>
          <pose frame=''>0.000577 -0.046301 -0.020592 0 -0 0</pose>
          <mass>0.0709944</mass>
          <inertia>
            <ixx>0.000150339</ixx>
            <ixy>9.85293e-07</ixy>
            <ixz>4.29279e-07</ixz>
            <iyy>6.97108e-05</iyy>
            <iyz>-3.53439e-05</iyz>
            <izz>0.000145966</izz>
          </inertia>
        </inertial>
        <collision name='R_Link6_collision'>
          <pose frame=''>0 0 0 0 -0 0</pose>
          <geometry>
            <mesh>
              <scale>1 1 1</scale>
              <uri>/home/zjy/catkin_ws/src/wust_robot/wust_robot_description/meshes/R_Link6.STL</uri>
            </mesh>
          </geometry>
          <surface>
            <contact>
              <ode/>
            </contact>
            <friction>
              <ode/>
              <torsional>
                <ode/>
              </torsional>
            </friction>
            <bounce/>
          </surface>
          <max_contacts>10</max_contacts>
        </collision>
        <visual name='R_Link6_visual'>
          <pose frame=''>0 0 0 0 -0 0</pose>
          <geometry>
            <mesh>
              <scale>1 1 1</scale>
              <uri>/home/zjy/catkin_ws/src/wust_robot/wust_robot_description/meshes/R_Link6.STL</uri>
            </mesh>
          </geometry>
          <material>
            <script>
              <uri>file://media/materials/scripts/gazebo.material</uri>
              <name>Gazebo/FlatBlack</name>
            </script>
          </material>
        </visual>
        <gravity>1</gravity>
        <velocity_decay/>
        <self_collide>0</self_collide>
        <kinematic>0</kinematic>
      </link>
      <joint name='R_joint6' type='revolute'>
        <child>R_Link6</child>
        <parent>R_Link5</parent>
        <axis>
          <xyz>-0.866867 -0.49854 0</xyz>
          <limit>
            <lower>-2.09</lower>
            <upper>2.09</upper>
            <effort>67</effort>
            <velocity>1.57</velocity>
          </limit>
          <dynamics>
            <spring_reference>0</spring_reference>
            <spring_stiffness>0</spring_stiffness>
          </dynamics>
          <use_parent_model_frame>1</use_parent_model_frame>
        </axis>
      </joint>
      <link name='R_Link7'>
        <pose frame=''>0.135046 -0.80143 1.17017 -0 -1.56231 2.09271</pose>
        <inertial>
          <pose frame=''>4.6e-05 1e-06 0.021461 0 -0 0</pose>
          <mass>0.069592</mass>
          <inertia>
            <ixx>0.000100578</ixx>
            <ixy>-8.86468e-08</ixy>
            <ixz>-5.47757e-08</ixz>
            <iyy>8.85998e-05</iyy>
            <iyz>6.35169e-09</iyz>
            <izz>8.88089e-05</izz>
          </inertia>
        </inertial>
        <collision name='R_Link7_collision'>
          <pose frame=''>0 0 0 0 -0 0</pose>
          <geometry>
            <mesh>
              <scale>1 1 1</scale>
              <uri>/home/zjy/catkin_ws/src/wust_robot/wust_robot_description/meshes/R_Link7.STL</uri>
            </mesh>
          </geometry>
          <surface>
            <contact>
              <ode>
                <kp>1e+08</kp>
                <kd>1</kd>
                <max_vel>1</max_vel>
                <min_depth>0.01</min_depth>
              </ode>
            </contact>
            <friction>
              <ode>
                <mu>200</mu>
                <mu2>200</mu2>
              </ode>
              <torsional>
                <ode/>
              </torsional>
            </friction>
            <bounce/>
          </surface>
          <max_contacts>10</max_contacts>
        </collision>
        <visual name='R_Link7_visual'>
          <pose frame=''>0 0 0 0 -0 0</pose>
          <geometry>
            <mesh>
              <scale>1 1 1</scale>
              <uri>/home/zjy/catkin_ws/src/wust_robot/wust_robot_description/meshes/R_Link7.STL</uri>
            </mesh>
          </geometry>
          <material>
            <ambient>0.792157 0.819608 0.933333 1</ambient>
            <diffuse>0.792157 0.819608 0.933333 1</diffuse>
            <specular>0.1 0.1 0.1 1</specular>
            <emissive>0 0 0 0</emissive>
            <script>
              <uri>__default__</uri>
              <name>__default__</name>
            </script>
          </material>
        </visual>
        <gravity>1</gravity>
        <velocity_decay/>
        <self_collide>0</self_collide>
        <kinematic>0</kinematic>
      </link>
      <joint name='R_joint7' type='revolute'>
        <child>R_Link7</child>
        <parent>R_Link6</parent>
        <axis>
          <xyz>-0.498525 0.866834 -0.008487</xyz>
          <limit>
            <lower>-3.05</lower>
            <upper>3.05</upper>
            <effort>33</effort>
            <velocity>1.57</velocity>
          </limit>
          <dynamics>
            <spring_reference>0</spring_reference>
            <spring_stiffness>0</spring_stiffness>
          </dynamics>
          <use_parent_model_frame>1</use_parent_model_frame>
        </axis>
      </joint>
      <link name='R_left_finger'>
        <pose frame=''>0.188432 -0.838096 1.17047 -0.001743 -0.010795 -1.57079</pose>
        <inertial>
          <pose frame=''>0.026096 0.026849 1.7e-05 0 -0 0</pose>
          <mass>0.0222032</mass>
          <inertia>
            <ixx>5.17634e-06</ixx>
            <ixy>-5.08077e-06</ixy>
            <ixz>3.86266e-09</ixz>
            <iyy>1.09633e-05</iyy>
            <iyz>-2.46942e-10</iyz>
            <izz>1.31832e-05</izz>
          </inertia>
        </inertial>
        <collision name='R_left_finger_collision'>
          <pose frame=''>0 0 0 0 -0 0</pose>
          <geometry>
            <mesh>
              <scale>1 1 1</scale>
              <uri>/home/zjy/catkin_ws/src/wust_robot/wust_robot_description/meshes/R_left_finger.STL</uri>
            </mesh>
          </geometry>
          <surface>
            <contact>
              <ode>
                <kp>1e+08</kp>
                <kd>1</kd>
                <max_vel>0.1</max_vel>
                <min_depth>0.01</min_depth>
              </ode>
            </contact>
            <friction>
              <ode>
                <mu>200</mu>
                <mu2>200</mu2>
              </ode>
              <torsional>
                <ode/>
              </torsional>
            </friction>
            <bounce/>
          </surface>
          <max_contacts>10</max_contacts>
        </collision>
        <visual name='R_left_finger_visual'>
          <pose frame=''>0 0 0 0 -0 0</pose>
          <geometry>
            <mesh>
              <scale>1 1 1</scale>
              <uri>/home/zjy/catkin_ws/src/wust_robot/wust_robot_description/meshes/R_left_finger.STL</uri>
            </mesh>
          </geometry>
          <material>
            <ambient>0.792157 0.819608 0.933333 1</ambient>
            <diffuse>0.792157 0.819608 0.933333 1</diffuse>
            <specular>0.1 0.1 0.1 1</specular>
            <emissive>0 0 0 0</emissive>
            <script>
              <uri>__default__</uri>
              <name>__default__</name>
            </script>
          </material>
        </visual>
        <gravity>1</gravity>
        <velocity_decay/>
        <self_collide>0</self_collide>
        <kinematic>0</kinematic>
      </link>
      <joint name='R_left_joint' type='revolute'>
        <child>R_left_finger</child>
        <parent>R_Link7</parent>
        <axis>
          <xyz>0.001743 0.010795 0.99994</xyz>
          <limit>
            <lower>-0.36</lower>
            <upper>0.36</upper>
            <effort>33</effort>
            <velocity>1.57</velocity>
          </limit>
          <dynamics>
            <spring_reference>0</spring_reference>
            <spring_stiffness>0</spring_stiffness>
          </dynamics>
          <use_parent_model_frame>1</use_parent_model_frame>
        </axis>
      </joint>
      <link name='R_right_finger'>
        <pose frame=''>0.139888 -0.866011 1.17086 -0.010803 0.001753 -1e-06</pose>
        <inertial>
          <pose frame=''>0.009007 -0.036187 -1.7e-05 0 -0 0</pose>
          <mass>0.0220975</mass>
          <inertia>
            <ixx>1.08406e-05</ixx>
            <ixy>5.1118e-06</ixy>
            <ixz>-3.55147e-09</ixz>
            <iyy>5.29285e-06</iyy>
            <iyz>1.38784e-09</iyz>
            <izz>1.31809e-05</izz>
          </inertia>
        </inertial>
        <collision name='R_right_finger_collision'>
          <pose frame=''>0 0 0 0 -0 0</pose>
          <geometry>
            <mesh>
              <scale>1 1 1</scale>
              <uri>/home/zjy/catkin_ws/src/wust_robot/wust_robot_description/meshes/R_right_finger.STL</uri>
            </mesh>
          </geometry>
          <surface>
            <contact>
              <ode>
                <kp>1e+08</kp>
                <kd>1</kd>
                <max_vel>0.1</max_vel>
                <min_depth>0.01</min_depth>
              </ode>
            </contact>
            <friction>
              <ode>
                <mu>200</mu>
                <mu2>200</mu2>
              </ode>
              <torsional>
                <ode/>
              </torsional>
            </friction>
            <bounce/>
          </surface>
          <max_contacts>10</max_contacts>
        </collision>
        <visual name='R_right_finger_visual'>
          <pose frame=''>0 0 0 0 -0 0</pose>
          <geometry>
            <mesh>
              <scale>1 1 1</scale>
              <uri>/home/zjy/catkin_ws/src/wust_robot/wust_robot_description/meshes/R_right_finger.STL</uri>
            </mesh>
          </geometry>
          <material>
            <ambient>0.792157 0.819608 0.933333 1</ambient>
            <diffuse>0.792157 0.819608 0.933333 1</diffuse>
            <specular>0.1 0.1 0.1 1</specular>
            <emissive>0 0 0 0</emissive>
            <script>
              <uri>__default__</uri>
              <name>__default__</name>
            </script>
          </material>
        </visual>
        <gravity>1</gravity>
        <velocity_decay/>
        <self_collide>0</self_collide>
        <kinematic>0</kinematic>
      </link>
      <joint name='R_right_joint' type='revolute'>
        <child>R_right_finger</child>
        <parent>R_Link7</parent>
        <axis>
          <xyz>0.001753 0.010803 0.99994</xyz>
          <limit>
            <lower>-0.36</lower>
            <upper>0.36</upper>
            <effort>33</effort>
            <velocity>1.57</velocity>
          </limit>
          <dynamics>
            <spring_reference>0</spring_reference>
            <spring_stiffness>0</spring_stiffness>
          </dynamics>
          <use_parent_model_frame>1</use_parent_model_frame>
        </axis>
      </joint>
      <link name='wheel_Link1'>
        <pose frame=''>-0.103621 0.316965 0.0402 1.5708 -0 2.61799</pose>
        <inertial>
          <pose frame=''>0 -0 -0.003202 0 -0 0</pose>
          <mass>0.784918</mass>
          <inertia>
            <ixx>0.00103508</ixx>
            <ixy>-1.20507e-09</ixy>
            <ixz>-1.4077e-11</ixz>
            <iyy>0.00103511</iyy>
            <iyz>-1.29208e-12</iyz>
            <izz>0.00137479</izz>
          </inertia>
        </inertial>
        <collision name='wheel_Link1_collision'>
          <pose frame=''>0 0 0 0 -0 0</pose>
          <geometry>
            <mesh>
              <scale>1 1 1</scale>
              <uri>/home/zjy/catkin_ws/src/wust_robot/wust_robot_description/meshes/wheel_Link1.STL</uri>
            </mesh>
          </geometry>
          <max_contacts>10</max_contacts>
          <surface>
            <contact>
              <ode/>
            </contact>
            <bounce/>
            <friction>
              <torsional>
                <ode/>
              </torsional>
              <ode/>
            </friction>
          </surface>
        </collision>
        <visual name='wheel_Link1_visual'>
          <pose frame=''>0 0 0 0 -0 0</pose>
          <geometry>
            <mesh>
              <scale>1 1 1</scale>
              <uri>/home/zjy/catkin_ws/src/wust_robot/wust_robot_description/meshes/wheel_Link1.STL</uri>
            </mesh>
          </geometry>
        </visual>
        <self_collide>0</self_collide>
        <kinematic>0</kinematic>
        <gravity>1</gravity>
      </link>
      <joint name='wheel_joint1' type='revolute'>
        <child>wheel_Link1</child>
        <parent>base_dummy</parent>
        <axis>
          <xyz>0.5 0.866025 0</xyz>
          <limit>
            <lower>-1e+16</lower>
            <upper>1e+16</upper>
          </limit>
          <dynamics>
            <spring_reference>0</spring_reference>
            <spring_stiffness>0</spring_stiffness>
          </dynamics>
          <use_parent_model_frame>1</use_parent_model_frame>
        </axis>
      </joint>
      <link name='wheel_Link2'>
        <pose frame=''>-0.652621 0 0.0402 1.5708 0 -1.5708</pose>
        <inertial>
          <pose frame=''>0 -0 -0.003202 0 -0 0</pose>
          <mass>0.784918</mass>
          <inertia>
            <ixx>0.00103508</ixx>
            <ixy>-2.85682e-09</ixy>
            <ixz>1.18111e-13</ixz>
            <iyy>0.00103511</iyy>
            <iyz>-6.67149e-12</iyz>
            <izz>0.00137479</izz>
          </inertia>
        </inertial>
        <collision name='wheel_Link2_collision'>
          <pose frame=''>0 0 0 0 -0 0</pose>
          <geometry>
            <mesh>
              <scale>1 1 1</scale>
              <uri>/home/zjy/catkin_ws/src/wust_robot/wust_robot_description/meshes/wheel_Link2.STL</uri>
            </mesh>
          </geometry>
          <max_contacts>10</max_contacts>
          <surface>
            <contact>
              <ode/>
            </contact>
            <bounce/>
            <friction>
              <torsional>
                <ode/>
              </torsional>
              <ode/>
            </friction>
          </surface>
        </collision>
        <visual name='wheel_Link2_visual'>
          <pose frame=''>0 0 0 0 -0 0</pose>
          <geometry>
            <mesh>
              <scale>1 1 1</scale>
              <uri>/home/zjy/catkin_ws/src/wust_robot/wust_robot_description/meshes/wheel_Link2.STL</uri>
            </mesh>
          </geometry>
        </visual>
        <self_collide>0</self_collide>
        <kinematic>0</kinematic>
        <gravity>1</gravity>
      </link>
      <joint name='wheel_joint2' type='revolute'>
        <child>wheel_Link2</child>
        <parent>base_dummy</parent>
        <axis>
          <xyz>-1 0 0</xyz>
          <limit>
            <lower>-1e+16</lower>
            <upper>1e+16</upper>
          </limit>
          <dynamics>
            <spring_reference>0</spring_reference>
            <spring_stiffness>0</spring_stiffness>
          </dynamics>
          <use_parent_model_frame>1</use_parent_model_frame>
        </axis>
      </joint>
      <link name='wheel_Link3'>
        <pose frame=''>-0.103621 -0.316965 0.0402 1.5708 -0 0.523599</pose>
        <inertial>
          <pose frame=''>-0 -0 -0.003202 0 -0 0</pose>
          <mass>0.784918</mass>
          <inertia>
            <ixx>0.00103508</ixx>
            <ixy>-8.54797e-10</ixy>
            <ixz>9.34219e-12</ixz>
            <iyy>0.00103511</iyy>
            <iyz>-1.46548e-13</iyz>
            <izz>0.00137479</izz>
          </inertia>
        </inertial>
        <collision name='wheel_Link3_collision'>
          <pose frame=''>0 0 0 0 -0 0</pose>
          <geometry>
            <mesh>
              <scale>1 1 1</scale>
              <uri>/home/zjy/catkin_ws/src/wust_robot/wust_robot_description/meshes/wheel_Link3.STL</uri>
            </mesh>
          </geometry>
          <max_contacts>10</max_contacts>
          <surface>
            <contact>
              <ode/>
            </contact>
            <bounce/>
            <friction>
              <torsional>
                <ode/>
              </torsional>
              <ode/>
            </friction>
          </surface>
        </collision>
        <visual name='wheel_Link3_visual'>
          <pose frame=''>0 0 0 0 -0 0</pose>
          <geometry>
            <mesh>
              <scale>1 1 1</scale>
              <uri>/home/zjy/catkin_ws/src/wust_robot/wust_robot_description/meshes/wheel_Link3.STL</uri>
            </mesh>
          </geometry>
        </visual>
        <self_collide>0</self_collide>
        <kinematic>0</kinematic>
        <gravity>1</gravity>
      </link>
      <joint name='wheel_joint3' type='revolute'>
        <child>wheel_Link3</child>
        <parent>base_dummy</parent>
        <axis>
          <xyz>-0.5 0.866025 0</xyz>
          <limit>
            <lower>-1e+16</lower>
            <upper>1e+16</upper>
          </limit>
          <dynamics>
            <spring_reference>0</spring_reference>
            <spring_stiffness>0</spring_stiffness>
          </dynamics>
          <use_parent_model_frame>1</use_parent_model_frame>
        </axis>
      </joint>
      <plugin name='gazebo_ros_control' filename='libgazebo_ros_control.so'>
        <robotNamespace>/wust_robot</robotNamespace>
        <robotSimType>gazebo_ros_control/DefaultRobotHWSim</robotSimType>
        <legacyModeNS>true</legacyModeNS>
      </plugin>
      <plugin name='gazebo_grasp_fix_1eft' filename='libgazebo_grasp_fix.so'>
        <arm>
          <arm_name>left_arm</arm_name>
          <palm_link>L_Link7</palm_link>
          <gripper_link>L_left_finger</gripper_link>
          <gripper_link>L_right_finger</gripper_link>
        </arm>
        <arm>
          <arm_name>right_arm</arm_name>
          <palm_link>R_Link7</palm_link>
          <gripper_link>R_left_finger</gripper_link>
          <gripper_link>R_right_finger</gripper_link>
        </arm>
        <forces_angle_tolerance>100</forces_angle_tolerance>
        <update_rate>4</update_rate>
        <grip_count_threshold>4</grip_count_threshold>
        <max_grip_count>8</max_grip_count>
        <release_tolerance>0.003</release_tolerance>
        <disable_collisions_on_attach>false</disable_collisions_on_attach>
        <contact_topic>__default_topic__</contact_topic>
        <robotNamespace>/</robotNamespace>
      </plugin>
      <static>0</static>
      <plugin name='mpo_500_controller' filename='libgazebo_ros_planar_move.so'>
        <commandTopic>cmd_vel</commandTopic>
        <leftFrontJoint>wheel_joint1</leftFrontJoint>
        <rightFrontJoint>wheel_joint2</rightFrontJoint>
        <leftRearJoint>wheel_joint3</leftRearJoint>
        <odometryTopic>odom</odometryTopic>
        <odometryFrame>odom</odometryFrame>
        <odometryRate>20.0</odometryRate>
        <robotBaseFrame>base_dummy</robotBaseFrame>
        <robotNamespace>/</robotNamespace>
      </plugin>
      <pose frame=''>0 0 0 0 -0 0</pose>
    </model>
    <model name='table_model'>
      <link name='table_top_link'>
        <pose frame=''>0 0 0 0 -0 0</pose>
        <inertial>
          <pose frame=''>0.8 0 0.535 0 -0 0</pose>
          <mass>50</mass>
          <inertia>
            <ixx>92.845</ixx>
            <ixy>0</ixy>
            <ixz>0</ixz>
            <iyy>12.845</iyy>
            <iyz>0</iyz>
            <izz>101.04</izz>
          </inertia>
        </inertial>
        <collision name='table_top_link_collision'>
          <pose frame=''>0.8 0 0.875 0 -0 0</pose>
          <geometry>
            <box>
              <size>1 3 0.05</size>
            </box>
          </geometry>
          <surface>
            <contact>
              <ode>
                <kp>1e+06</kp>
                <kd>1</kd>
              </ode>
            </contact>
            <friction>
              <ode>
                <mu>50</mu>
                <mu2>50</mu2>
              </ode>
              <torsional>
                <ode/>
              </torsional>
            </friction>
            <bounce/>
          </surface>
          <max_contacts>10</max_contacts>
        </collision>
        <collision name='table_top_link_fixed_joint_lump__leg1_link_collision_1'>
          <pose frame=''>1.3 1.5 0.45 0 -0 0</pose>
          <geometry>
            <cylinder>
              <length>0.9</length>
              <radius>0.02</radius>
            </cylinder>
          </geometry>
          <surface>
            <contact>
              <ode>
                <kp>1e+07</kp>
                <kd>1</kd>
              </ode>
            </contact>
            <friction>
              <ode>
                <mu>1000</mu>
                <mu2>1000</mu2>
              </ode>
              <torsional>
                <ode/>
              </torsional>
            </friction>
            <bounce/>
          </surface>
          <max_contacts>10</max_contacts>
        </collision>
        <collision name='table_top_link_fixed_joint_lump__leg2_link_collision_2'>
          <pose frame=''>0.3 1.5 0.45 0 -0 0</pose>
          <geometry>
            <cylinder>
              <length>0.9</length>
              <radius>0.02</radius>
            </cylinder>
          </geometry>
          <surface>
            <contact>
              <ode>
                <kp>1e+07</kp>
                <kd>1</kd>
              </ode>
            </contact>
            <friction>
              <ode>
                <mu>1000</mu>
                <mu2>1000</mu2>
              </ode>
              <torsional>
                <ode/>
              </torsional>
            </friction>
            <bounce/>
          </surface>
          <max_contacts>10</max_contacts>
        </collision>
        <collision name='table_top_link_fixed_joint_lump__leg3_link_collision_3'>
          <pose frame=''>1.3 -1.5 0.45 0 -0 0</pose>
          <geometry>
            <cylinder>
              <length>0.9</length>
              <radius>0.02</radius>
            </cylinder>
          </geometry>
          <surface>
            <contact>
              <ode>
                <kp>1e+07</kp>
                <kd>1</kd>
              </ode>
            </contact>
            <friction>
              <ode>
                <mu>1000</mu>
                <mu2>1000</mu2>
              </ode>
              <torsional>
                <ode/>
              </torsional>
            </friction>
            <bounce/>
          </surface>
          <max_contacts>10</max_contacts>
        </collision>
        <collision name='table_top_link_fixed_joint_lump__leg4_link_collision_4'>
          <pose frame=''>0.3 -1.5 0.45 0 -0 0</pose>
          <geometry>
            <cylinder>
              <length>0.9</length>
              <radius>0.02</radius>
            </cylinder>
          </geometry>
          <surface>
            <contact>
              <ode>
                <kp>1e+07</kp>
                <kd>1</kd>
              </ode>
            </contact>
            <friction>
              <ode>
                <mu>1000</mu>
                <mu2>1000</mu2>
              </ode>
              <torsional>
                <ode/>
              </torsional>
            </friction>
            <bounce/>
          </surface>
          <max_contacts>10</max_contacts>
        </collision>
        <visual name='table_top_link_visual'>
          <pose frame=''>0.8 0 0.875 0 -0 0</pose>
          <geometry>
            <box>
              <size>1 3 0.05</size>
            </box>
          </geometry>
          <material>
            <script>
              <name>Gazebo/Wood</name>
              <uri>file://media/materials/scripts/gazebo.material</uri>
            </script>
          </material>
        </visual>
        <visual name='table_top_link_fixed_joint_lump__leg1_link_visual_1'>
          <pose frame=''>1.3 1.5 0.45 0 -0 0</pose>
          <geometry>
            <cylinder>
              <length>0.9</length>
              <radius>0.02</radius>
            </cylinder>
          </geometry>
          <material>
            <script>
              <name>Gazebo/Red</name>
              <uri>file://media/materials/scripts/gazebo.material</uri>
            </script>
          </material>
        </visual>
        <visual name='table_top_link_fixed_joint_lump__leg2_link_visual_2'>
          <pose frame=''>0.3 1.5 0.45 0 -0 0</pose>
          <geometry>
            <cylinder>
              <length>0.9</length>
              <radius>0.02</radius>
            </cylinder>
          </geometry>
          <material>
            <script>
              <name>Gazebo/Red</name>
              <uri>file://media/materials/scripts/gazebo.material</uri>
            </script>
          </material>
        </visual>
        <visual name='table_top_link_fixed_joint_lump__leg3_link_visual_3'>
          <pose frame=''>1.3 -1.5 0.45 0 -0 0</pose>
          <geometry>
            <cylinder>
              <length>0.9</length>
              <radius>0.02</radius>
            </cylinder>
          </geometry>
          <material>
            <script>
              <name>Gazebo/Red</name>
              <uri>file://media/materials/scripts/gazebo.material</uri>
            </script>
          </material>
        </visual>
        <visual name='table_top_link_fixed_joint_lump__leg4_link_visual_4'>
          <pose frame=''>0.3 -1.5 0.45 0 -0 0</pose>
          <geometry>
            <cylinder>
              <length>0.9</length>
              <radius>0.02</radius>
            </cylinder>
          </geometry>
          <material>
            <script>
              <name>Gazebo/Red</name>
              <uri>file://media/materials/scripts/gazebo.material</uri>
            </script>
          </material>
        </visual>
        <velocity_decay/>
        <velocity_decay/>
        <velocity_decay/>
        <velocity_decay/>
        <gravity>1</gravity>
        <velocity_decay/>
        <self_collide>1</self_collide>
        <kinematic>0</kinematic>
      </link>
      <static>1</static>
      <pose frame=''>0 0 0.01 0 -0 0</pose>
    </model>
    <model name='cafe_table_0'>
      <link name='link'>
        <pose frame=''>0 0 0 0 -0 0</pose>
        <self_collide>0</self_collide>
        <kinematic>0</kinematic>
        <gravity>1</gravity>
        <inertial>
          <mass>1</mass>
          <pose frame=''>0 0 0 0 -0 0</pose>
          <inertia>
            <ixx>1</ixx>
            <ixy>0</ixy>
            <ixz>0</ixz>
            <iyy>1</iyy>
            <iyz>0</iyz>
            <izz>1</izz>
          </inertia>
        </inertial>
        <visual name='visual'>
          <geometry>
            <mesh>
              <uri>model://cafe_table/meshes/cafe_table.dae</uri>
              <scale>1 1 1</scale>
            </mesh>
          </geometry>
          <pose frame=''>0 0 0 0 -0 0</pose>
          <cast_shadows>1</cast_shadows>
          <transparency>0</transparency>
          <material>
            <shader type='vertex'>
              <normal_map>__default__</normal_map>
            </shader>
          </material>
        </visual>
        <collision name='surface'>
          <laser_retro>0</laser_retro>
          <max_contacts>10</max_contacts>
          <pose frame=''>0 0 0.755 0 -0 0</pose>
          <geometry>
            <box>
              <size>0.913 0.913 0.04</size>
            </box>
          </geometry>
          <surface>
            <friction>
              <ode>
                <mu>1</mu>
                <mu2>1</mu2>
                <fdir1>0 0 0</fdir1>
                <slip1>0</slip1>
                <slip2>0</slip2>
              </ode>
              <torsional>
                <coefficient>1</coefficient>
                <patch_radius>0</patch_radius>
                <surface_radius>0</surface_radius>
                <use_patch_radius>1</use_patch_radius>
                <ode>
                  <slip>0</slip>
                </ode>
              </torsional>
            </friction>
            <bounce>
              <restitution_coefficient>0</restitution_coefficient>
              <threshold>1e+06</threshold>
            </bounce>
            <contact>
              <collide_without_contact>0</collide_without_contact>
              <collide_without_contact_bitmask>1</collide_without_contact_bitmask>
              <collide_bitmask>1</collide_bitmask>
              <ode>
                <soft_cfm>0</soft_cfm>
                <soft_erp>0.2</soft_erp>
                <kp>1e+13</kp>
                <kd>1</kd>
                <max_vel>0.01</max_vel>
                <min_depth>0</min_depth>
              </ode>
              <bullet>
                <split_impulse>1</split_impulse>
                <split_impulse_penetration_threshold>-0.01</split_impulse_penetration_threshold>
                <soft_cfm>0</soft_cfm>
                <soft_erp>0.2</soft_erp>
                <kp>1e+13</kp>
                <kd>1</kd>
              </bullet>
            </contact>
          </surface>
        </collision>
        <collision name='column'>
          <laser_retro>0</laser_retro>
          <max_contacts>10</max_contacts>
          <pose frame=''>0 0 0.37 0 -0 0</pose>
          <geometry>
            <box>
              <size>0.042 0.042 0.74</size>
            </box>
          </geometry>
          <surface>
            <friction>
              <ode>
                <mu>1</mu>
                <mu2>1</mu2>
                <fdir1>0 0 0</fdir1>
                <slip1>0</slip1>
                <slip2>0</slip2>
              </ode>
              <torsional>
                <coefficient>1</coefficient>
                <patch_radius>0</patch_radius>
                <surface_radius>0</surface_radius>
                <use_patch_radius>1</use_patch_radius>
                <ode>
                  <slip>0</slip>
                </ode>
              </torsional>
            </friction>
            <bounce>
              <restitution_coefficient>0</restitution_coefficient>
              <threshold>1e+06</threshold>
            </bounce>
            <contact>
              <collide_without_contact>0</collide_without_contact>
              <collide_without_contact_bitmask>1</collide_without_contact_bitmask>
              <collide_bitmask>1</collide_bitmask>
              <ode>
                <soft_cfm>0</soft_cfm>
                <soft_erp>0.2</soft_erp>
                <kp>1e+13</kp>
                <kd>1</kd>
                <max_vel>0.01</max_vel>
                <min_depth>0</min_depth>
              </ode>
              <bullet>
                <split_impulse>1</split_impulse>
                <split_impulse_penetration_threshold>-0.01</split_impulse_penetration_threshold>
                <soft_cfm>0</soft_cfm>
                <soft_erp>0.2</soft_erp>
                <kp>1e+13</kp>
                <kd>1</kd>
              </bullet>
            </contact>
          </surface>
        </collision>
        <collision name='base'>
          <laser_retro>0</laser_retro>
          <max_contacts>10</max_contacts>
          <pose frame=''>0 0 0.02 0 -0 0</pose>
          <geometry>
            <box>
              <size>0.56 0.56 0.04</size>
            </box>
          </geometry>
          <surface>
            <friction>
              <ode>
                <mu>1</mu>
                <mu2>1</mu2>
                <fdir1>0 0 0</fdir1>
                <slip1>0</slip1>
                <slip2>0</slip2>
              </ode>
              <torsional>
                <coefficient>1</coefficient>
                <patch_radius>0</patch_radius>
                <surface_radius>0</surface_radius>
                <use_patch_radius>1</use_patch_radius>
                <ode>
                  <slip>0</slip>
                </ode>
              </torsional>
            </friction>
            <bounce>
              <restitution_coefficient>0</restitution_coefficient>
              <threshold>1e+06</threshold>
            </bounce>
            <contact>
              <collide_without_contact>0</collide_without_contact>
              <collide_without_contact_bitmask>1</collide_without_contact_bitmask>
              <collide_bitmask>1</collide_bitmask>
              <ode>
                <soft_cfm>0</soft_cfm>
                <soft_erp>0.2</soft_erp>
                <kp>1e+13</kp>
                <kd>1</kd>
                <max_vel>0.01</max_vel>
                <min_depth>0</min_depth>
              </ode>
              <bullet>
                <split_impulse>1</split_impulse>
                <split_impulse_penetration_threshold>-0.01</split_impulse_penetration_threshold>
                <soft_cfm>0</soft_cfm>
                <soft_erp>0.2</soft_erp>
                <kp>1e+13</kp>
                <kd>1</kd>
              </bullet>
            </contact>
          </surface>
        </collision>
      </link>
      <static>1</static>
      <allow_auto_disable>1</allow_auto_disable>
      <pose frame=''>-3.273 2.10937 0 0 -0 0</pose>
    </model>
    <state world_name='default'>
      <sim_time>946 90000000</sim_time>
      <real_time>251 670167862</real_time>
      <wall_time>1560664085 437737988</wall_time>
      <iterations>237165</iterations>
      <model name='cafe_table_0'>
        <pose frame=''>-3.5 1.5 0 0 -0 0</pose>
        <scale>1 1 1</scale>
        <link name='link'>
          <pose frame=''>-3.5 1.5 0 0 -0 0</pose>
          <velocity>0 0 0 0 -0 0</velocity>
          <acceleration>0 0 0 0 -0 0</acceleration>
          <wrench>0 0 0 0 -0 0</wrench>
        </link>
      </model>
      <model name='ground_plane'>
        <pose frame=''>0 0 0 0 -0 0</pose>
        <scale>1 1 1</scale>
        <link name='link'>
          <pose frame=''>0 0 0 0 -0 0</pose>
          <velocity>0 0 0 0 -0 0</velocity>
          <acceleration>0 0 0 0 -0 0</acceleration>
          <wrench>0 0 0 0 -0 0</wrench>
        </link>
      </model>
      <model name='pallet2'>
        <pose frame=''>0.219976 0 0.929998 -1.5708 -0 1.57</pose>
        <scale>1 1 1</scale>
        <link name='link_0'>
          <pose frame=''>0.219976 0 0.929998 -1.5708 -0 1.57</pose>
          <velocity>0 0 0 0 -0 0</velocity>
          <acceleration>0 0 0 0 -0 0</acceleration>
          <wrench>0 0 0 0 -0 0</wrench>
        </link>
      </model>
      <model name='table_model'>
        <pose frame=''>-0.2 0.8 0 0 -0 0</pose>
        <scale>1 1 1</scale>
        <link name='table_top_link'>
          <pose frame=''>-0.2 0.8 0 0 -0 0</pose>
          <velocity>0 0 0 0 -0 0</velocity>
          <acceleration>0 0 0 0 -0 0</acceleration>
          <wrench>0 0 0 0 -0 0</wrench>
        </link>
      </model>
      <model name='wust_robot'>
        <pose frame=''>0.001339 -0.01244 0.022234 1e-06 1.5e-05 -0.03574</pose>
        <scale>1 1 1</scale>
        <link name='L_Link1'>
          <pose frame=''>-0.242358 0.122544 1.17595 -3.07538 1.56043 -2.06564</pose>
          <velocity>9e-06 -5e-06 -0.009358 0.009279 -0.007983 -0.000116</velocity>
          <acceleration>0.018401 -0.004831 -8.60223 -1.019 -1.08103 2.47752</acceleration>
          <wrench>0.004159 -0.001092 -1.9441 0 -0 0</wrench>
        </link>
        <link name='L_Link2'>
          <pose frame=''>-0.229456 0.240801 1.1746 1.62637 1.55907 -2.07629</pose>
          <velocity>-1.7e-05 -4.1e-05 -0.008503 0.002679 -0.010621 -0.00022</velocity>
          <acceleration>0.010585 -0.049098 -7.7921 -1.47955 1.46355 -0.514351</acceleration>
          <wrench>0.002235 -0.010367 -1.64534 0 -0 0</wrench>
        </link>
        <link name='L_Link3'>
          <pose frame=''>-0.083994 0.374542 1.1696 -3.03092 1.55899 -2.02117</pose>
          <velocity>-1.4e-05 -5.3e-05 -0.007082 0.00224 -0.012679 -0.000464</velocity>
          <acceleration>0.006823 -0.073541 -6.42182 -2.41282 0.537747 2.29129</acceleration>
          <wrench>0.001193 -0.012862 -1.12318 0 -0 0</wrench>
        </link>
        <link name='L_Link4'>
          <pose frame=''>-0.072176 0.486752 1.16858 1.67143 1.55801 -2.03122</pose>
          <velocity>7e-06 -0.000101 -0.006648 -0.001255 -0.012515 -0.000594</velocity>
          <acceleration>0.054331 -0.135956 -6.01445 0.065932 0.985346 -0.148313</acceleration>
          <wrench>0.00756 -0.018917 -0.836856 0 -0 0</wrench>
        </link>
        <link name='L_Link5'>
          <pose frame=''>0.062569 0.607756 1.16425 -2.96325 1.55786 -1.9535</pose>
          <velocity>9.1e-05 -0.00017 -0.00506 -0.004831 -0.013988 -0.00085</velocity>
          <acceleration>0.112514 -0.194149 -4.78022 3.03647 -1.55916 0.861834</acceleration>
          <wrench>0.010961 -0.018914 -0.465682 0 -0 0</wrench>
        </link>
        <link name='L_Link6'>
          <pose frame=''>0.068922 0.683831 1.16317 1.73757 1.55703 -1.96507</pose>
          <velocity>0.000143 -0.000208 -0.005292 -0.006311 -0.011407 -0.001028</velocity>
          <acceleration>0.18495 -0.258559 -4.98997 1.28825 -0.746242 1.98698</acceleration>
          <wrench>0.01313 -0.018356 -0.354261 0 -0 0</wrench>
        </link>
        <link name='L_Link7'>
          <pose frame=''>0.167314 0.774424 1.15988 -2.97463 1.55703 -1.96488</pose>
          <velocity>0.000248 -0.000312 -0.004592 -0.006949 -0.011014 -0.00107</velocity>
          <acceleration>0.271186 -0.326398 -4.59207 1.56021 1.55465 2.22807</acceleration>
          <wrench>0.018872 -0.022715 -0.319569 0 -0 0</wrench>
        </link>
        <link name='L_left_finger'>
          <pose frame=''>0.174677 0.838762 1.15892 -0.009456 0.011533 0.749607</pose>
          <velocity>0.000327 -0.000325 -0.00504 -0.005161 -0.005396 -0.001207</velocity>
          <acceleration>0.372925 -0.3401 -5.16908 2.88886 -0.123985 -0.967093</acceleration>
          <wrench>0.00828 -0.007551 -0.11477 0 -0 0</wrench>
        </link>
        <link name='L_right_finger'>
          <pose frame=''>0.222093 0.808969 1.15926 -0.009463 0.011523 0.749611</pose>
          <velocity>0.00029 -0.000375 -0.004286 -0.004562 -0.008382 -0.001218</velocity>
          <acceleration>0.324505 -0.410819 -4.16667 -2.15971 0.050857 -0.839115</acceleration>
          <wrench>0.007205 -0.009122 -0.092513 0 -0 0</wrench>
        </link>
        <link name='R_Link1'>
          <pose frame=''>-0.252096 -0.137425 1.17876 -0.080436 -1.56237 2.13741</pose>
          <velocity>2.7e-05 -6e-06 -0.009358 -0.009866 -0.007267 -0.000352</velocity>
          <acceleration>0.007534 -0.016813 -8.60144 -2.71517 -1.39654 -0.742287</acceleration>
          <wrench>0.001703 -0.003799 -1.94383 0 -0 0</wrench>
        </link>
        <link name='R_Link2'>
          <pose frame=''>-0.248077 -0.256317 1.17998 -1.66186 -1.56374 2.14804</pose>
          <velocity>9e-06 -3.2e-05 -0.008503 -0.003489 -0.010375 -0.000283</velocity>
          <acceleration>-0.019465 -0.042062 -7.79105 -0.27405 0.794054 -0.681334</acceleration>
          <wrench>-0.00411 -0.008882 -1.64512 0 -0 0</wrench>
        </link>
        <link name='R_Link3'>
          <pose frame=''>-0.113014 -0.400596 1.18375 -0.182421 -1.56367 2.2394</pose>
          <velocity>-4.8e-05 -6.8e-05 -0.007079 -0.003209 -0.01245 -0.000337</velocity>
          <acceleration>-0.066898 -0.081057 -6.41918 0.676123 0.818323 2.29707</acceleration>
          <wrench>-0.0117 -0.014177 -1.12272 0 -0 0</wrench>
        </link>
        <link name='R_Link4'>
          <pose frame=''>-0.109623 -0.513376 1.18473 -1.77892 -1.56464 2.2651</pose>
          <velocity>-9.1e-05 -7.6e-05 -0.006645 0.000262 -0.012509 -0.000304</velocity>
          <acceleration>-0.121648 -0.092464 -6.01215 -2.90725 0.574659 0.051661</acceleration>
          <wrench>-0.016926 -0.012865 -0.836531 0 -0 0</wrench>
        </link>
        <link name='R_Link5'>
          <pose frame=''>0.015699 -0.644145 1.18803 -0.36251 -1.56437 2.4195</pose>
          <velocity>-0.000168 -0.000115 -0.005057 0.003716 -0.014224 -0.000324</velocity>
          <acceleration>-0.176602 -0.12329 -4.77885 1.55138 -0.899715 1.09116</acceleration>
          <wrench>-0.017204 -0.012011 -0.465549 0 -0 0</wrench>
        </link>
        <link name='R_Link6'>
          <pose frame=''>0.016345 -0.720487 1.1886 -1.9837 -1.56514 2.46989</pose>
          <velocity>-0.000198 -0.00012 -0.005288 0.005333 -0.011705 -0.000354</velocity>
          <acceleration>-0.218822 -0.138616 -4.98855 2.3132 -0.982318 2.63896</acceleration>
          <wrench>-0.015535 -0.009841 -0.354159 0 -0 0</wrench>
        </link>
        <link name='R_Link7'>
          <pose frame=''>0.107688 -0.818209 1.19095 -0.412862 -1.56515 2.46985</pose>
          <velocity>-0.000259 -0.000159 -0.004591 0.006001 -0.011344 -0.000358</velocity>
          <acceleration>-0.267566 -0.163882 -4.5907 0.526438 1.24472 -0.30526</acceleration>
          <wrench>-0.01862 -0.011405 -0.319476 0 -0 0</wrench>
        </link>
        <link name='R_left_finger'>
          <pose frame=''>0.15973 -0.856759 1.19112 -0.001433 -0.006798 -1.6065</pose>
          <velocity>-0.000274 -0.000179 -0.004329 0.004574 -0.008454 -0.000417</velocity>
          <acceleration>-0.286995 -0.19087 -4.23327 0.32265 -0.531421 2.96905</acceleration>
          <wrench>-0.006372 -0.004238 -0.093992 0 -0 0</wrench>
        </link>
        <link name='R_right_finger'>
          <pose frame=''>0.11022 -0.882924 1.19139 -0.00681 0.001452 -0.035688</pose>
          <velocity>-0.000286 -0.000162 -0.004986 0.003838 -0.007212 -0.00047</velocity>
          <acceleration>-0.30511 -0.166529 -5.07039 -2.63024 -1.0984 -0.434946</acceleration>
          <wrench>-0.006742 -0.00368 -0.112043 0 -0 0</wrench>
        </link>
        <link name='base_dummy'>
          <pose frame=''>0.001339 -0.01244 0.022234 1e-06 1.5e-05 -0.03574</pose>
          <velocity>-2.5e-05 1.3e-05 -0.009812 -1e-06 5.2e-05 4.3e-05</velocity>
          <acceleration>-0.000632 0.001804 -9.79905 -0.000434 0.05178 0.043043</acceleration>
          <wrench>-0.065764 0.187837 -1020.4 0 -0 0</wrench>
        </link>
        <link name='wheel_Link1'>
          <pose frame=''>-0.090892 0.308023 0.06245 1.57074 0.368495 2.58223</pose>
          <velocity>0.000665 0.000639 -0.013229 -0.012638 0.007912 -0.000873</velocity>
          <acceleration>0.662668 0.640034 -13.1815 3.06949 1.5125 1.98253</acceleration>
          <wrench>0.52014 0.502374 -10.3464 0 -0 0</wrench>
        </link>
        <link name='wheel_Link2'>
          <pose frame=''>-0.650862 0.010879 0.06245 1.57072 0.615254 -1.60658</pose>
          <velocity>-0.000723 0.000199 -0.011334 -0.000413 -0.011559 -0.000448</velocity>
          <acceleration>-0.722692 0.197262 -11.2974 -0.413296 1.00747 -0.594816</acceleration>
          <wrench>-0.567254 0.154835 -8.86756 0 -0 0</wrench>
        </link>
        <link name='wheel_Link3'>
          <pose frame=''>-0.113542 -0.325497 0.062449 -1.57074 -0.676668 -2.65376</pose>
          <velocity>0.000169 -0.000822 -0.013327 0.010999 0.005836 -0.000813</velocity>
          <acceleration>0.171726 -0.82079 -13.2872 -1.5676 -0.446626 -1.07971</acceleration>
          <wrench>0.134791 -0.644253 -10.4294 0 -0 0</wrench>
        </link>
      </model>
      <light name='sun'>
        <pose frame=''>0 0 10 0 -0 0</pose>
      </light>
    </state>
    <gui fullscreen='0'>
      <camera name='user_camera'>
        <pose frame=''>2.44058 -1.10417 1.93666 0 0.251643 2.46418</pose>
        <view_controller>orbit</view_controller>
        <projection_type>perspective</projection_type>
      </camera>
    </gui>
    <model name='pallet2'>
      <link name='link_0'>
        <pose frame=''>0 0 0 0 -0 0</pose>
        <inertial>
          <mass>1</mass>
          <inertia>
            <ixx>0.166667</ixx>
            <ixy>0</ixy>
            <ixz>0</ixz>
            <iyy>0.166667</iyy>
            <iyz>0</iyz>
            <izz>0.166667</izz>
          </inertia>
        </inertial>
        <visual name='visual'>
          <pose frame=''>0 0 0 0 -0 0</pose>
          <geometry>
            <mesh>
              <uri>/home/zjy/catkin_ws/src/models/pallet2/meshes/pallet2.STL</uri>
              <scale>1 1 1</scale>
            </mesh>
          </geometry>
          <material>
            <lighting>1</lighting>
            <script>
              <uri>file://media/materials/scripts/gazebo.material</uri>
              <name>Gazebo/Grey</name>
            </script>
            <ambient>0.3 0.3 0.3 1</ambient>
            <diffuse>0.7 0.7 0.7 1</diffuse>
            <specular>0.01 0.01 0.01 1</specular>
            <emissive>0 0 0 1</emissive>
          </material>
          <cast_shadows>1</cast_shadows>
          <transparency>0</transparency>
        </visual>
        <collision name='collision'>
          <laser_retro>0</laser_retro>
          <max_contacts>10</max_contacts>
          <pose frame=''>0 0 0 0 -0 0</pose>
          <geometry>
            <mesh>
              <uri>/home/zjy/catkin_ws/src/models/pallet2/meshes/pallet2.STL</uri>
              <scale>1 1 1</scale>
            </mesh>
          </geometry>
          <surface>
            <friction>
              <ode>
                <mu>1</mu>
                <mu2>1</mu2>
                <fdir1>0 0 0</fdir1>
                <slip1>0</slip1>
                <slip2>0</slip2>
              </ode>
              <torsional>
                <coefficient>1</coefficient>
                <patch_radius>0</patch_radius>
                <surface_radius>0</surface_radius>
                <use_patch_radius>1</use_patch_radius>
                <ode>
                  <slip>0</slip>
                </ode>
              </torsional>
            </friction>
            <bounce>
              <restitution_coefficient>0</restitution_coefficient>
              <threshold>1e+06</threshold>
            </bounce>
            <contact>
              <collide_without_contact>0</collide_without_contact>
              <collide_without_contact_bitmask>1</collide_without_contact_bitmask>
              <collide_bitmask>1</collide_bitmask>
              <ode>
                <soft_cfm>0</soft_cfm>
                <soft_erp>0.2</soft_erp>
                <kp>1e+13</kp>
                <kd>1</kd>
                <max_vel>0.01</max_vel>
                <min_depth>0</min_depth>
              </ode>
              <bullet>
                <split_impulse>1</split_impulse>
                <split_impulse_penetration_threshold>-0.01</split_impulse_penetration_threshold>
                <soft_cfm>0</soft_cfm>
                <soft_erp>0.2</soft_erp>
                <kp>1e+13</kp>
                <kd>1</kd>
              </bullet>
            </contact>
          </surface>
        </collision>
        <self_collide>0</self_collide>
        <kinematic>0</kinematic>
        <gravity>1</gravity>
      </link>
      <static>0</static>
      <allow_auto_disable>1</allow_auto_disable>
      <pose frame=''>0 0 0 0 -0 0</pose>
    </model>
  </world>
</sdf>
